Workbook

Sheet 進捗確認
A1: 進捗確認
A2: ※ 黄色いセルが入力欄です。日々の件数は下の「日別 実績入力」表に入力、売れた対象機種は「機種販売入力」、目標は「目標設定」シートで入力します(それ以外は自動計算)。
A3: 対象月 | B3: =目標設定!C3 | C3: 月の日数 | D3: =目標設定!C4 | E3: 最終入力日 | F3: =SUMPRODUCT(MAX(A42:A72*O42:O72)) | G3: 経過率 | H3: =IF(D3>0,F3/D3,0)
A4: ▶ 日別 実績入力へ移動(下へスクロール) | E4: =IF(機種販売入力!L6>0,"⚠ 機種販売入力に販売日が未入力の行が"&機種販売入力!L6&"行あります。日別・累計に反映されません。","")
A5: 項目 | B5: 月間目標 | C5: 累計実績 | D5: 達成率 | E5: 残数 | F5: 理想ペース (目標×経過率) | G5: 理想との差 | H5: 残り1日あたり 必要件数 | I5: 判定 | J5: 現在の配点 (ラダー) | K5: 次のラダー (達成率) | L5: 次のラダーの 配点 | M5: 次のラダーまで あと(件)
A6: 新規 | B6: =IF(N(目標設定!$D$7)>0,目標設定!$D$7,"-") | C6: =C73 | D6: =IF(ISNUMBER(B6),C6/B6,"-") | E6: =IF(ISNUMBER(B6),MAX(B6-C6,0),"-") | F6: =IF(ISNUMBER(B6),B6*$H$3,"-") | G6: =IF(ISNUMBER(B6),C6-F6,"-") | H6: =IF(ISNUMBER(B6),IF($D$3-$F$3>0,E6/($D$3-$F$3),E6),"-") | I6: =IF(NOT(ISNUMBER(B6)),"目標未設定",IF(C6>=B6,"達成",IF(C6>=F6,"順調","遅れ"))) | J6: =IF(ISNUMBER(D6),INDEX(ラダー!$B$5:$B$34,MATCH(SUMPRODUCT(MAX((ラダー!$A$5:$A$34<=ROUND(D6,6))*ラダー!$A$5:$A$34)),ラダー!$A$5:$A$34,0)),"-") | K6: =IF(ISNUMBER(D6),IFERROR(SMALL(ラダー!$A$5:$A$34,COUNTIF(ラダー!$A$5:$A$34,"<="&ROUND(D6,6))+1),"最高段"),"-") | L6: =IF(ISNUMBER(K6),INDEX(ラダー!$B$5:$B$34,MATCH(K6,ラダー!$A$5:$A$34,0)),"-") | M6: =IF(ISNUMBER(K6),ROUNDUP(K6*B6-C6-0.000001,0),"-")
A7: MNP | B7: =IF(N(目標設定!$D$8)>0,目標設定!$D$8,"-") | C7: =D73 | D7: =IF(ISNUMBER(B7),C7/B7,"-") | E7: =IF(ISNUMBER(B7),MAX(B7-C7,0),"-") | F7: =IF(ISNUMBER(B7),B7*$H$3,"-") | G7: =IF(ISNUMBER(B7),C7-F7,"-") | H7: =IF(ISNUMBER(B7),IF($D$3-$F$3>0,E7/($D$3-$F$3),E7),"-") | I7: =IF(NOT(ISNUMBER(B7)),"目標未設定",IF(C7>=B7,"達成",IF(C7>=F7,"順調","遅れ"))) | J7: =IF(ISNUMBER(D7),INDEX(ラダー!$E$5:$E$34,MATCH(SUMPRODUCT(MAX((ラダー!$D$5:$D$34<=ROUND(D7,6))*ラダー!$D$5:$D$34)),ラダー!$D$5:$D$34,0)),"-") | K7: =IF(ISNUMBER(D7),IFERROR(SMALL(ラダー!$D$5:$D$34,COUNTIF(ラダー!$D$5:$D$34,"<="&ROUND(D7,6))+1),"最高段"),"-") | L7: =IF(ISNUMBER(K7),INDEX(ラダー!$E$5:$E$34,MATCH(K7,ラダー!$D$5:$D$34,0)),"-") | M7: =IF(ISNUMBER(K7),ROUNDUP(K7*B7-C7-0.000001,0),"-")
A8: 固定 | B8: =IF(N(目標設定!$D$9)>0,目標設定!$D$9,"-") | C8: =E73 | D8: =IF(ISNUMBER(B8),C8/B8,"-") | E8: =IF(ISNUMBER(B8),MAX(B8-C8,0),"-") | F8: =IF(ISNUMBER(B8),B8*$H$3,"-") | G8: =IF(ISNUMBER(B8),C8-F8,"-") | H8: =IF(ISNUMBER(B8),IF($D$3-$F$3>0,E8/($D$3-$F$3),E8),"-") | I8: =IF(NOT(ISNUMBER(B8)),"目標未設定",IF(C8>=B8,"達成",IF(C8>=F8,"順調","遅れ"))) | J8: =IF(ISNUMBER(D8),INDEX(ラダー!$K$5:$K$34,MATCH(SUMPRODUCT(MAX((ラダー!$J$5:$J$34<=ROUND(D8,6))*ラダー!$J$5:$J$34)),ラダー!$J$5:$J$34,0)),"-") | K8: =IF(ISNUMBER(D8),IFERROR(SMALL(ラダー!$J$5:$J$34,COUNTIF(ラダー!$J$5:$J$34,"<="&ROUND(D8,6))+1),"最高段"),"-") | L8: =IF(ISNUMBER(K8),INDEX(ラダー!$K$5:$K$34,MATCH(K8,ラダー!$J$5:$J$34,0)),"-") | M8: =IF(ISNUMBER(K8),ROUNDUP(K8*B8-C8-0.000001,0),"-")
A9: タブレット | B9: =IF(N(目標設定!$D$10)>0,目標設定!$D$10,"-") | C9: =F73 | D9: =IF(ISNUMBER(B9),C9/B9,"-") | E9: =IF(ISNUMBER(B9),MAX(B9-C9,0),"-") | F9: =IF(ISNUMBER(B9),B9*$H$3,"-") | G9: =IF(ISNUMBER(B9),C9-F9,"-") | H9: =IF(ISNUMBER(B9),IF($D$3-$F$3>0,E9/($D$3-$F$3),E9),"-") | I9: =IF(NOT(ISNUMBER(B9)),"目標未設定",IF(C9>=B9,"達成",IF(C9>=F9,"順調","遅れ"))) | J9: =IF(ISNUMBER(D9),INDEX(ラダー!$N$5:$N$34,MATCH(SUMPRODUCT(MAX((ラダー!$M$5:$M$34<=ROUND(D9,6))*ラダー!$M$5:$M$34)),ラダー!$M$5:$M$34,0)),"-") | K9: =IF(ISNUMBER(D9),IFERROR(SMALL(ラダー!$M$5:$M$34,COUNTIF(ラダー!$M$5:$M$34,"<="&ROUND(D9,6))+1),"最高段"),"-") | L9: =IF(ISNUMBER(K9),INDEX(ラダー!$N$5:$N$34,MATCH(K9,ラダー!$M$5:$M$34,0)),"-") | M9: =IF(ISNUMBER(K9),ROUNDUP(K9*B9-C9-0.000001,0),"-")
A10: 電気 | B10: =IF(N(目標設定!$D$11)>0,目標設定!$D$11,"-") | C10: =G73 | D10: =IF(ISNUMBER(B10),C10/B10,"-") | E10: =IF(ISNUMBER(B10),MAX(B10-C10,0),"-") | F10: =IF(ISNUMBER(B10),B10*$H$3,"-") | G10: =IF(ISNUMBER(B10),C10-F10,"-") | H10: =IF(ISNUMBER(B10),IF($D$3-$F$3>0,E10/($D$3-$F$3),E10),"-") | I10: =IF(NOT(ISNUMBER(B10)),"目標未設定",IF(C10>=B10,"達成",IF(C10>=F10,"順調","遅れ"))) | J10: =IF(ISNUMBER(D10),INDEX(ラダー!$Q$5:$Q$34,MATCH(SUMPRODUCT(MAX((ラダー!$P$5:$P$34<=ROUND(D10,6))*ラダー!$P$5:$P$34)),ラダー!$P$5:$P$34,0)),"-") | K10: =IF(ISNUMBER(D10),IFERROR(SMALL(ラダー!$P$5:$P$34,COUNTIF(ラダー!$P$5:$P$34,"<="&ROUND(D10,6))+1),"最高段"),"-") | L10: =IF(ISNUMBER(K10),INDEX(ラダー!$Q$5:$Q$34,MATCH(K10,ラダー!$P$5:$P$34,0)),"-") | M10: =IF(ISNUMBER(K10),ROUNDUP(K10*B10-C10-0.000001,0),"-")
A11: PPCD申込 | B11: - | C11: =H73 | D11: =IF(ISNUMBER(目標設定!$F$12),目標設定!$F$12,"-") | E11: - | F11: - | G11: - | H11: - | I11: =IF(ISNUMBER(D11),"手入力率","率未入力") | J11: =IF(ISNUMBER(D11),INDEX(ラダー!$T$5:$T$34,MATCH(SUMPRODUCT(MAX((ラダー!$S$5:$S$34<=ROUND(D11,6))*ラダー!$S$5:$S$34)),ラダー!$S$5:$S$34,0)),"-") | K11: =IF(ISNUMBER(D11),IFERROR(SMALL(ラダー!$S$5:$S$34,COUNTIF(ラダー!$S$5:$S$34,"<="&ROUND(D11,6))+1),"最高段"),"-") | L11: =IF(ISNUMBER(K11),INDEX(ラダー!$T$5:$T$34,MATCH(K11,ラダー!$S$5:$S$34,0)),"-") | M11: -
A12: SB Gold申込 | B12: - | C12: =I73 | D12: =IF(ISNUMBER(目標設定!$F$13),目標設定!$F$13,"-") | E12: - | F12: - | G12: - | H12: - | I12: =IF(ISNUMBER(D12),"手入力率","率未入力") | J12: =IF(ISNUMBER(D12),INDEX(ラダー!$W$5:$W$34,MATCH(SUMPRODUCT(MAX((ラダー!$V$5:$V$34<=ROUND(D12,6))*ラダー!$V$5:$V$34)),ラダー!$V$5:$V$34,0)),"-") | K12: =IF(ISNUMBER(D12),IFERROR(SMALL(ラダー!$V$5:$V$34,COUNTIF(ラダー!$V$5:$V$34,"<="&ROUND(D12,6))+1),"最高段"),"-") | L12: =IF(ISNUMBER(K12),INDEX(ラダー!$W$5:$W$34,MATCH(K12,ラダー!$V$5:$V$34,0)),"-") | M12: -
A13: 戦略機種(Pt) | B13: =IF(N(目標設定!$D$14)>0,目標設定!$D$14,"-") | C13: =J73 | D13: =IF(ISNUMBER(B13),C13/B13,"-") | E13: =IF(ISNUMBER(B13),MAX(B13-C13,0),"-") | F13: =IF(ISNUMBER(B13),B13*$H$3,"-") | G13: =IF(ISNUMBER(B13),C13-F13,"-") | H13: =IF(ISNUMBER(B13),IF($D$3-$F$3>0,E13/($D$3-$F$3),E13),"-") | I13: =IF(NOT(ISNUMBER(B13)),"目標未設定",IF(C13>=B13,"達成",IF(C13>=F13,"順調","遅れ"))) | J13: =IF(ISNUMBER(D13),INDEX(ラダー!$Z$5:$Z$34,MATCH(SUMPRODUCT(MAX((ラダー!$Y$5:$Y$34<=ROUND(D13,6))*ラダー!$Y$5:$Y$34)),ラダー!$Y$5:$Y$34,0)),"-") | K13: =IF(ISNUMBER(D13),IFERROR(SMALL(ラダー!$Y$5:$Y$34,COUNTIF(ラダー!$Y$5:$Y$34,"<="&ROUND(D13,6))+1),"最高段"),"-") | L13: =IF(ISNUMBER(K13),INDEX(ラダー!$Z$5:$Z$34,MATCH(K13,ラダー!$Y$5:$Y$34,0)),"-") | M13: =IF(ISNUMBER(K13),ROUNDUP(K13*B13-C13-0.000001,0),"-")
A14: Watch | B14: =IF(N(目標設定!$D$15)>0,目標設定!$D$15,"-") | C14: =K73 | D14: =IF(ISNUMBER(B14),C14/B14,"-") | E14: =IF(ISNUMBER(B14),MAX(B14-C14,0),"-") | F14: =IF(ISNUMBER(B14),B14*$H$3,"-") | G14: =IF(ISNUMBER(B14),C14-F14,"-") | H14: =IF(ISNUMBER(B14),IF($D$3-$F$3>0,E14/($D$3-$F$3),E14),"-") | I14: =IF(NOT(ISNUMBER(B14)),"目標未設定",IF(C14>=B14,"達成",IF(C14>=F14,"順調","遅れ"))) | J14: =IF(ISNUMBER(D14),INDEX(ラダー!$AC$5:$AC$34,MATCH(SUMPRODUCT(MAX((ラダー!$AB$5:$AB$34<=ROUND(D14,6))*ラダー!$AB$5:$AB$34)),ラダー!$AB$5:$AB$34,0)),"-") | K14: =IF(ISNUMBER(D14),IFERROR(SMALL(ラダー!$AB$5:$AB$34,COUNTIF(ラダー!$AB$5:$AB$34,"<="&ROUND(D14,6))+1),"最高段"),"-") | L14: =IF(ISNUMBER(K14),INDEX(ラダー!$AC$5:$AC$34,MATCH(K14,ラダー!$AB$5:$AB$34,0)),"-") | M14: =IF(ISNUMBER(K14),ROUNDUP(K14*B14-C14-0.000001,0),"-")
A15: 機変 | B15: =IF(N(目標設定!$D$16)>0,目標設定!$D$16,"-") | C15: =L73 | D15: =IF(ISNUMBER(B15),C15/B15,"-") | E15: =IF(ISNUMBER(B15),MAX(B15-C15,0),"-") | F15: =IF(ISNUMBER(B15),B15*$H$3,"-") | G15: =IF(ISNUMBER(B15),C15-F15,"-") | H15: =IF(ISNUMBER(B15),IF($D$3-$F$3>0,E15/($D$3-$F$3),E15),"-") | I15: =IF(NOT(ISNUMBER(B15)),"目標未設定",IF(C15>=B15,"達成",IF(C15>=F15,"順調","遅れ"))) | J15: =IF(ISNUMBER(D15),INDEX(ラダー!$H$5:$H$34,MATCH(SUMPRODUCT(MAX((ラダー!$G$5:$G$34<=ROUND(D15,6))*ラダー!$G$5:$G$34)),ラダー!$G$5:$G$34,0)),"-") | K15: =IF(ISNUMBER(D15),IFERROR(SMALL(ラダー!$G$5:$G$34,COUNTIF(ラダー!$G$5:$G$34,"<="&ROUND(D15,6))+1),"最高段"),"-") | L15: =IF(ISNUMBER(K15),INDEX(ラダー!$H$5:$H$34,MATCH(K15,ラダー!$G$5:$G$34,0)),"-") | M15: =IF(ISNUMBER(K15),ROUNDUP(K15*B15-C15-0.000001,0),"-")
A16: DMM | B16: =IF(N(目標設定!$D$17)>0,目標設定!$D$17,"-") | C16: =M73 | D16: =IF(ISNUMBER(B16),C16/B16,"-") | E16: =IF(ISNUMBER(B16),MAX(B16-C16,0),"-") | F16: =IF(ISNUMBER(B16),B16*$H$3,"-") | G16: =IF(ISNUMBER(B16),C16-F16,"-") | H16: =IF(ISNUMBER(B16),IF($D$3-$F$3>0,E16/($D$3-$F$3),E16),"-") | I16: =IF(NOT(ISNUMBER(B16)),"目標未設定",IF(C16>=B16,"達成",IF(C16>=F16,"順調","遅れ"))) | J16: ラダーなし | K16: - | L16: - | M16: -
A17: YouTube | B17: =IF(N(目標設定!$D$18)>0,目標設定!$D$18,"-") | C17: =N73 | D17: =IF(ISNUMBER(B17),C17/B17,"-") | E17: =IF(ISNUMBER(B17),MAX(B17-C17,0),"-") | F17: =IF(ISNUMBER(B17),B17*$H$3,"-") | G17: =IF(ISNUMBER(B17),C17-F17,"-") | H17: =IF(ISNUMBER(B17),IF($D$3-$F$3>0,E17/($D$3-$F$3),E17),"-") | I17: =IF(NOT(ISNUMBER(B17)),"目標未設定",IF(C17>=B17,"達成",IF(C17>=F17,"順調","遅れ"))) | J17: ラダーなし | K17: - | L17: - | M17: -
A18: SBプラン(ペイトク) | B18: =IF(N(目標設定!$D$19)>0,目標設定!$D$19,"-") | C18: =N(目標設定!$F$19) | D18: =IF(ISNUMBER(B18),C18/B18,"-") | E18: =IF(ISNUMBER(B18),MAX(B18-C18,0),"-") | F18: =IF(ISNUMBER(B18),B18*$H$3,"-") | G18: =IF(ISNUMBER(B18),C18-F18,"-") | H18: =IF(ISNUMBER(B18),IF($D$3-$F$3>0,E18/($D$3-$F$3),E18),"-") | I18: =IF(NOT(ISNUMBER(B18)),"目標未設定",IF(C18>=B18,"達成",IF(C18>=F18,"順調","遅れ"))) | J18: ラダーなし | K18: - | L18: - | M18: -
A19: SBプラン(大容量) | B19: =IF(N(目標設定!$D$20)>0,目標設定!$D$20,"-") | C19: =N(目標設定!$F$20) | D19: =IF(ISNUMBER(B19),C19/B19,"-") | E19: =IF(ISNUMBER(B19),MAX(B19-C19,0),"-") | F19: =IF(ISNUMBER(B19),B19*$H$3,"-") | G19: =IF(ISNUMBER(B19),C19-F19,"-") | H19: =IF(ISNUMBER(B19),IF($D$3-$F$3>0,E19/($D$3-$F$3),E19),"-") | I19: =IF(NOT(ISNUMBER(B19)),"目標未設定",IF(C19>=B19,"達成",IF(C19>=F19,"順調","遅れ"))) | J19: ラダーなし | K19: - | L19: - | M19: -
A20: SB通話OP | B20: =IF(N(目標設定!$D$21)>0,目標設定!$D$21,"-") | C20: =N(目標設定!$F$21) | D20: =IF(ISNUMBER(B20),C20/B20,"-") | E20: =IF(ISNUMBER(B20),MAX(B20-C20,0),"-") | F20: =IF(ISNUMBER(B20),B20*$H$3,"-") | G20: =IF(ISNUMBER(B20),C20-F20,"-") | H20: =IF(ISNUMBER(B20),IF($D$3-$F$3>0,E20/($D$3-$F$3),E20),"-") | I20: =IF(NOT(ISNUMBER(B20)),"目標未設定",IF(C20>=B20,"達成",IF(C20>=F20,"順調","遅れ"))) | J20: =IF(ISNUMBER(D20),INDEX(ラダー!$AG$5:$AG$34,MATCH(SUMPRODUCT(MAX((ラダー!$AF$5:$AF$34<=ROUND(D20,6))*ラダー!$AF$5:$AF$34)),ラダー!$AF$5:$AF$34,0)),"-") | K20: =IF(ISNUMBER(D20),IFERROR(SMALL(ラダー!$AF$5:$AF$34,COUNTIF(ラダー!$AF$5:$AF$34,"<="&ROUND(D20,6))+1),"最高段"),"-") | L20: =IF(ISNUMBER(K20),INDEX(ラダー!$AG$5:$AG$34,MATCH(K20,ラダー!$AF$5:$AF$34,0)),"-") | M20: =IF(ISNUMBER(K20),ROUNDUP(K20*B20-C20-0.000001,0),"-")
A21: SB保証 | B21: =IF(N(目標設定!$D$22)>0,目標設定!$D$22,"-") | C21: =N(目標設定!$F$22) | D21: =IF(ISNUMBER(B21),C21/B21,"-") | E21: =IF(ISNUMBER(B21),MAX(B21-C21,0),"-") | F21: =IF(ISNUMBER(B21),B21*$H$3,"-") | G21: =IF(ISNUMBER(B21),C21-F21,"-") | H21: =IF(ISNUMBER(B21),IF($D$3-$F$3>0,E21/($D$3-$F$3),E21),"-") | I21: =IF(NOT(ISNUMBER(B21)),"目標未設定",IF(C21>=B21,"達成",IF(C21>=F21,"順調","遅れ"))) | J21: =IF(ISNUMBER(D21),INDEX(ラダー!$AJ$5:$AJ$34,MATCH(SUMPRODUCT(MAX((ラダー!$AI$5:$AI$34<=ROUND(D21,6))*ラダー!$AI$5:$AI$34)),ラダー!$AI$5:$AI$34,0)),"-") | K21: =IF(ISNUMBER(D21),IFERROR(SMALL(ラダー!$AI$5:$AI$34,COUNTIF(ラダー!$AI$5:$AI$34,"<="&ROUND(D21,6))+1),"最高段"),"-") | L21: =IF(ISNUMBER(K21),INDEX(ラダー!$AJ$5:$AJ$34,MATCH(K21,ラダー!$AI$5:$AI$34,0)),"-") | M21: =IF(ISNUMBER(K21),ROUNDUP(K21*B21-C21-0.000001,0),"-")
A22: SBセキュリティ | B22: =IF(N(目標設定!$D$23)>0,目標設定!$D$23,"-") | C22: =N(目標設定!$F$23) | D22: =IF(ISNUMBER(B22),C22/B22,"-") | E22: =IF(ISNUMBER(B22),MAX(B22-C22,0),"-") | F22: =IF(ISNUMBER(B22),B22*$H$3,"-") | G22: =IF(ISNUMBER(B22),C22-F22,"-") | H22: =IF(ISNUMBER(B22),IF($D$3-$F$3>0,E22/($D$3-$F$3),E22),"-") | I22: =IF(NOT(ISNUMBER(B22)),"目標未設定",IF(C22>=B22,"達成",IF(C22>=F22,"順調","遅れ"))) | J22: =IF(ISNUMBER(D22),INDEX(ラダー!$AM$5:$AM$34,MATCH(SUMPRODUCT(MAX((ラダー!$AL$5:$AL$34<=ROUND(D22,6))*ラダー!$AL$5:$AL$34)),ラダー!$AL$5:$AL$34,0)),"-") | K22: =IF(ISNUMBER(D22),IFERROR(SMALL(ラダー!$AL$5:$AL$34,COUNTIF(ラダー!$AL$5:$AL$34,"<="&ROUND(D22,6))+1),"最高段"),"-") | L22: =IF(ISNUMBER(K22),INDEX(ラダー!$AM$5:$AM$34,MATCH(K22,ラダー!$AL$5:$AL$34,0)),"-") | M22: =IF(ISNUMBER(K22),ROUNDUP(K22*B22-C22-0.000001,0),"-")
A23: SB店スマ | B23: =IF(N(目標設定!$D$24)>0,目標設定!$D$24,"-") | C23: =N(目標設定!$F$24) | D23: =IF(ISNUMBER(B23),C23/B23,"-") | E23: =IF(ISNUMBER(B23),MAX(B23-C23,0),"-") | F23: =IF(ISNUMBER(B23),B23*$H$3,"-") | G23: =IF(ISNUMBER(B23),C23-F23,"-") | H23: =IF(ISNUMBER(B23),IF($D$3-$F$3>0,E23/($D$3-$F$3),E23),"-") | I23: =IF(NOT(ISNUMBER(B23)),"目標未設定",IF(C23>=B23,"達成",IF(C23>=F23,"順調","遅れ"))) | J23: ラダーなし | K23: - | L23: - | M23: -
A24: SB支払設定 | B24: =IF(N(目標設定!$D$25)>0,目標設定!$D$25,"-") | C24: =N(目標設定!$F$25) | D24: =IF(ISNUMBER(B24),C24/B24,"-") | E24: =IF(ISNUMBER(B24),MAX(B24-C24,0),"-") | F24: =IF(ISNUMBER(B24),B24*$H$3,"-") | G24: =IF(ISNUMBER(B24),C24-F24,"-") | H24: =IF(ISNUMBER(B24),IF($D$3-$F$3>0,E24/($D$3-$F$3),E24),"-") | I24: =IF(NOT(ISNUMBER(B24)),"目標未設定",IF(C24>=B24,"達成",IF(C24>=F24,"順調","遅れ"))) | J24: =IF(ISNUMBER(D24),INDEX(ラダー!$AS$5:$AS$34,MATCH(SUMPRODUCT(MAX((ラダー!$AR$5:$AR$34<=ROUND(D24,6))*ラダー!$AR$5:$AR$34)),ラダー!$AR$5:$AR$34,0)),"-") | K24: =IF(ISNUMBER(D24),IFERROR(SMALL(ラダー!$AR$5:$AR$34,COUNTIF(ラダー!$AR$5:$AR$34,"<="&ROUND(D24,6))+1),"最高段"),"-") | L24: =IF(ISNUMBER(K24),INDEX(ラダー!$AS$5:$AS$34,MATCH(K24,ラダー!$AR$5:$AR$34,0)),"-") | M24: =IF(ISNUMBER(K24),ROUNDUP(K24*B24-C24-0.000001,0),"-")
A25: 合計(目標設定済み項目) | B25: =SUMIF(目標設定!$D$7:$D$25,">0") | C25: =SUMIF($B6:$B24,">0",$C6:$C24) | D25: =IF(B25>0,C25/B25,"-") | E25: =MAX(B25-C25,0) | F25: =B25*$H$3 | G25: =C25-F25 | H25: =IF($D$3-$F$3>0,E25/($D$3-$F$3),E25) | I25: =IF(B25=0,"-",IF(C25>=B25,"達成",IF(C25>=F25,"順調","遅れ"))) | J25: =SUM(J6:J24)
A26: ※ 達成率=累計実績÷月間目標 / 残数=目標−実績 / 判定:実績≧目標→達成、実績≧理想ペース→順調、それ以外→遅れ
A27: ※ 配点は「ラダー」シートの表から、現在の達成率に対応する点数を表示します(合計点は上表の項目の合計で、店舗全体の点数ではありません)。「あと」は件数ですが、戦略機種(Pt)のみPtです。PPCD申込・SB Goldは「目標設定」に入力した申込率で判定します。No.13〜19(SBプラン〜SB支払設定)は日別入力がなく、「目標設定」シートの目標(D列)と実績(F列)を手入力した数値で計算します(SBプラン・SB店スマはラダーなし)。
A28: ■ 戦略機種 点数(現時点)
A29: 現在の戦略Pt(点数) | B29: =C13
A30: 戦略対象機種の販売台数 | B30: =機種販売入力!L4
A31: 最終入力日の加算Pt | B31: =IF($F$3>0,INDEX(J42:J72,$F$3),0)
A32: 戦略Pt目標 | B32: =B13
A33: 点数達成率(Pt÷目標) | B33: =D13
A34: 残りPt | B34: =E13
A35: 販売日 未入力の行数 | B35: =機種販売入力!L6
A36: ※ 点数は「機種販売入力」で選んだ機種の(機種Pt+戦略Pt)×台数の合計です(機種ごとの内訳は「機種マスタ」)。
A40: ■ 日別 実績入力(その日の件数を黄色いセルに入力・累計は自動計算)
A41: 日 | B41: 日付 | C41: 新規 | D41: MNP | E41: 固定 | F41: タブレット | G41: 電気 | H41: PPCD申込 | I41: SB Gold申込 | J41: 戦略機種(Pt) 自動加算 | K41: Watch | L41: 機変 | M41: DMM | N41: YouTube | O41: 入力
A42: 1 | B42: =IF(A42<=$D$3,目標設定!$C$3+A42-1,"") | E42: 4 | J42: =IF($B42="","",SUMIFS(機種販売入力!$I$4:$I$503,機種販売入力!$A$4:$A$503,$B42)) | K42: 1 | L42: 5 | M42: 2 | N42: 2 | O42: =IF(OR(COUNT(C42:I42,K42:N42)>0,N(J42)>0),1,0)
A43: 2 | B43: =IF(A43<=$D$3,目標設定!$C$3+A43-1,"") | C43: 2 | D43: 2 | J43: =IF($B43="","",SUMIFS(機種販売入力!$I$4:$I$503,機種販売入力!$A$4:$A$503,$B43)) | O43: =IF(OR(COUNT(C43:I43,K43:N43)>0,N(J43)>0),1,0)
...

Sheet 目標設定
B1: 目標設定(1ヶ月の目標値)
B3: 対象月(1日の日付) | C3: 46296 | D3: ※ 月が変わったら、この日付を新しい月の1日に変更してください。
B4: 月の日数 | C4: =DAY(EOMONTH(C3,0))
B6: No. | C6: 項目 | D6: 月間目標 | E6: 備考 | F6: 手入力欄 (No.6・7=率 / No.13〜19=実績の数値)
B7: 1 | C7: 新規 | D7: 88 | E7: SBYM対外新規
B8: 2 | C8: MNP | D8: 66
B9: 3 | C9: 固定 | D9: 51
B10: 4 | C10: タブレット | D10: 7
B11: 5 | C11: 電気 | D11: 12 | E11: でんき
B12: 6 | C12: PPCD申込 | D12: - | E12: 申込率を右の列に手入力
B13: 7 | C13: SB Gold申込 | D13: - | E13: 申込率を右の列に手入力
B14: 8 | C14: 戦略機種(Pt) | D14: 849 | E14: 目標はPt / 機種販売入力から自動加算
B15: 9 | C15: Watch | D15: 5 | E15: ウォッチ
B16: 10 | C16: 機変 | D16: 150
B17: 11 | C17: DMM | D17: 26
B18: 12 | C18: YouTube | D18: 46
B19: 13 | C19: SBプラン (ペイトク率) | E19: 目標=D列、実績=F列に数値を手入力(ラダーなし)
B20: 14 | C20: SBプラン (大容量率) | E20: 目標=D列、実績=F列に数値を手入力(ラダーなし)
B21: 15 | C21: SB通話OP | E21: 目標=D列、実績=F列に数値を手入力
B22: 16 | C22: SB保証 | E22: 目標=D列、実績=F列に数値を手入力
B23: 17 | C23: SBセキュリティ | E23: 目標=D列、実績=F列に数値を手入力
B24: 18 | C24: SB店スマ | E24: 目標=D列、実績=F列に数値を手入力(ラダーなし)
B25: 19 | C25: SB支払設定 | E25: 目標=D列、実績=F列に数値を手入力
B27: ※ 黄色のセル(青字)が入力欄です。目標が空欄の項目は、達成率が「-」と表示されます。
B28: ※ PPCD申込・SB Goldは分母の計算が複雑なため、申込率(例 25%)を右端の列に手入力すると、その率でラダーの配点を判定します。
B29: ※ No.13〜19は追加項目です。目標(D列)と実績(F列)に数値を手入力すると、「進捗確認」シートのYouTubeと合計の間に達成率・残数・判定などを表示します(SB通話OP・SB保証・SBセキュリティ・SB支払設定は、達成率に対応する配点も「ラダー」シートから表示)。

Sheet ラダー
A1: ラダー(達成率 → 配点)
A2: 「測定項目ラダー」の表です。達成率が「その段以上」になった最も高い段の配点が付きます。ラダーが変わったら黄色いセルを書き換えてください(段の追加は空き行へ)。右側にSB通話OP・SB保証・SBセキュリティ・SB店スマ・SB支払設定とSBプラン×大容量の表を追加しています(率は「目標設定」シートで手入力)。
A3: 新規 (SYスマホ対外新規達成率) | D3: MNP (SYスマホMNP達成率) | G3: 機変 (機変スマホ達成率) | J3: 固定 (固定達成率) | M3: タブレット (タブレット達成率) | P3: 電気 (でんき達成率) | S3: PPCD申込 (PPCD申込) | V3: SB Gold申込 (SBGold申込) | Y3: 戦略機種(Pt) (戦略機種) | AB3: Watch (Watch) | AF3: SB通話OP (SB通話OP) | AI3: SB保証 (SB保証) | AL3: SBセキュリティ (SBセキュリティ) | AO3: SB店スマ (ラダーなし) | AR3: SB支払設定 (SB支払設定) | AU3: SBプラン × 大容量 (ペイトク率 × 大容量率 → 配点)
A4: 達成率 | B4: 配点 | D4: 達成率 | E4: 配点 | G4: 達成率 | H4: 配点 | J4: 達成率 | K4: 配点 | M4: 達成率 | N4: 配点 | P4: 達成率 | Q4: 配点 | S4: 達成率 | T4: 配点 | V4: 達成率 | W4: 配点 | Y4: 達成率 | Z4: 配点 | AB4: 達成率 | AC4: 配点 | AD4: 全メーカー 得点 | AF4: 達成率 | AG4: 配点 | AI4: 達成率 | AJ4: 配点 | AL4: 達成率 | AM4: 配点 | AO4: 達成率 | AP4: 配点 | AR4: 達成率 | AS4: 配点 | AU4: ペイトク率↓ 大容量率→ | AV4: 0 | AW4: 0.6 | AX4: 0.65 | AY4: 0.7 | AZ4: 0.75 | BA4: 0.8
A5: 0 | B5: 0 | D5: 0 | E5: 0 | G5: 0 | H5: 0 | J5: 0 | K5: 0 | M5: 0 | N5: 0 | P5: 0 | Q5: 0 | S5: 0 | T5: 0 | V5: 0 | W5: 0 | Y5: 0 | Z5: 0 | AB5: 0 | AC5: 0 | AD5: 0 | AF5: 0 | AG5: 0 | AI5: 0 | AJ5: 0 | AL5: 0 | AM5: 0 | AO5: - | AP5: - | AR5: 0 | AS5: 0 | AU5: 0 | AV5: 0 | AW5: 0 | AX5: 0 | AY5: 0 | AZ5: 0 | BA5: 0
A6: 0.4 | B6: 5 | D6: 0.4 | E6: 30 | G6: 0.74 | H6: 5 | J6: 0.7 | K6: 5 | M6: 0.3 | N6: 2 | P6: 0.3 | Q6: 2 | S6: 0.1 | T6: 1 | V6: 0.05 | W6: 1 | Y6: 0.6 | Z6: 1 | AB6: 0.6 | AC6: 1 | AD6: 0 | AF6: 0.35 | AG6: 2 | AI6: 0.5 | AJ6: 2 | AL6: 0.2 | AM6: 2 | AR6: 0.3 | AS6: 1 | AU6: 0.2 | AV6: 0 | AW6: 3 | AX6: 6 | AY6: 9 | AZ6: 12 | BA6: 15
A7: 0.55 | B7: 10 | D7: 0.45 | E7: 35 | G7: 0.76 | H7: 10 | J7: 0.75 | K7: 10 | M7: 0.45 | N7: 4 | P7: 0.45 | Q7: 4 | S7: 0.15 | T7: 2 | V7: 0.1 | W7: 2 | Y7: 0.68 | Z7: 2 | AB7: 0.8 | AC7: 2 | AD7: 1 | AF7: 0.4 | AG7: 4 | AI7: 0.55 | AJ7: 4 | AL7: 0.25 | AM7: 4 | AR7: 0.4 | AS7: 2 | AU7: 0.25 | AV7: 0 | AW7: 6 | AX7: 9 | AY7: 12 | AZ7: 15 | BA7: 18
A8: 0.7 | B8: 15 | D8: 0.5 | E8: 40 | G8: 0.78 | H8: 15 | J8: 0.8 | K8: 15 | M8: 0.6 | N8: 6 | P8: 0.6 | Q8: 6 | S8: 0.2 | T8: 3 | Y8: 0.76 | Z8: 3 | AB8: 1 | AC8: 3 | AD8: 2 | AF8: 0.45 | AG8: 6 | AI8: 0.6 | AJ8: 6 | AL8: 0.3 | AM8: 6 | AU8: 0.3 | AV8: 0 | AW8: 9 | AX8: 12 | AY8: 15 | AZ8: 18 | BA8: 21
A9: 0.85 | B9: 20 | D9: 0.55 | E9: 45 | G9: 0.8 | H9: 20 | J9: 0.85 | K9: 20 | M9: 0.75 | N9: 8 | P9: 0.75 | Q9: 8 | S9: 0.25 | T9: 4 | Y9: 0.84 | Z9: 4 | AB9: 1.2 | AC9: 4 | AD9: 2 | AF9: 0.5 | AG9: 8 | AI9: 0.65 | AJ9: 8 | AL9: 0.35 | AM9: 8 | AU9: 0.35 | AV9: 0 | AW9: 12 | AX9: 15 | AY9: 18 | AZ9: 21 | BA9: 27
A10: 1 | B10: 25 | D10: 0.6 | E10: 50 | G10: 0.82 | H10: 25 | J10: 0.9 | K10: 25 | M10: 0.9 | N10: 10 | P10: 0.9 | Q10: 10 | S10: 0.3 | T10: 5 | Y10: 0.92 | Z10: 5 | AF10: 0.55 | AG10: 10 | AI10: 0.7 | AJ10: 10 | AL10: 0.4 | AM10: 10 | AU10: 0.4 | AV10: 0 | AW10: 15 | AX10: 18 | AY10: 21 | AZ10: 27 | BA10: 30
A11: 1.15 | B11: 30 | D11: 0.65 | E11: 55 | G11: 0.84 | H11: 30 | J11: 0.95 | K11: 30 | M11: 1.05 | N11: 12 | P11: 1.05 | Q11: 12 | S11: 0.35 | T11: 6 | Y11: 1 | Z11: 6
A12: 1.3 | B12: 35 | D12: 0.7 | E12: 60 | G12: 0.86 | H12: 35 | J12: 1 | K12: 35 | M12: 1.2 | N12: 14 | P12: 1.2 | Q12: 14 | Y12: 1.08 | Z12: 7
A13: 1.45 | B13: 40 | D13: 0.75 | E13: 65 | G13: 0.88 | H13: 40 | J13: 1.05 | K13: 40 | M13: 1.35 | N13: 16 | P13: 1.35 | Q13: 16 | Y13: 1.16 | Z13: 8
D14: 0.8 | E14: 70 | G14: 0.9 | H14: 45 | J14: 1.1 | K14: 45 | M14: 1.5 | N14: 18 | P14: 1.5 | Q14: 18
D15: 0.85 | E15: 75 | G15: 0.92 | H15: 50 | J15: 1.15 | K15: 50 | M15: 1.65 | N15: 20 | P15: 1.65 | Q15: 20
D16: 0.9 | E16: 80 | G16: 0.94 | H16: 55 | J16: 1.2 | K16: 55
D17: 0.95 | E17: 85 | G17: 0.96 | H17: 60 | J17: 1.25 | K17: 60
D18: 1 | E18: 90 | G18: 0.98 | H18: 65 | J18: 1.3 | K18: 65
D19: 1.05 | E19: 95 | G19: 1 | H19: 70 | J19: 1.35 | K19: 70
D20: 1.1 | E20: 100 | G20: 1.02 | H20: 75 | J20: 1.4 | K20: 75
D21: 1.15 | E21: 105 | G21: 1.04 | H21: 80 | J21: 1.45 | K21: 80
D22: 1.2 | E22: 110 | G22: 1.06 | H22: 85
D23: 1.25 | E23: 115 | G23: 1.08 | H23: 90
D24: 1.3 | E24: 120 | G24: 1.1 | H24: 95
D25: 1.35 | E25: 125 | G25: 1.12 | H25: 100
D26: 1.4 | E26: 130 | G26: 1.14 | H26: 105
G27: 1.16 | H27: 110

Sheet 機種販売入力
A1: 機種販売入力(対象機種が売れたら1行追加)
A2: 販売日・区分(SB/YM)・機種名(プルダウン)を選ぶだけで、その機種の(機種Pt+戦略Pt)×台数が自動加算されます(機種Ptの点数は機種マスタのQ〜R列で変更可。戦略Ptが空欄の機種は加算されません)。区分が空欄ならSBとして扱います。台数は空欄なら1台として計算します。販売日が空欄の行は日別に反映されません(赤く表示)。販売日は▼から選択(今日の日付は Ctrl+; でも入力可)。
A3: 販売日 | B3: 区分 (SB/YM) | C3: 機種名 | D3: 台数 (空欄=1台) | E3: カテゴリ | F3: 機種Pt | G3: 戦略Pt (1台あたり) | H3: 台数(計) | I3: 加算Pt (機種Pt+戦略Pt)×台数 | K3: 戦略Pt 累計 | L3: =SUM(I4:I503)
A4: 46296 | B4: SB | C4: iPhone 18 Pro Max(256GB) | E4: =IF($C4="","",IF($B4="YM",IFERROR(INDEX(機種マスタ!$I$4:$I$203,MATCH($C4,機種マスタ!$J$4:$J$203,0)),"未登録"),IFERROR(INDEX(機種マスタ!$A$4:$A$363,MATCH($C4,機種マスタ!$B$4:$B$363,0)),"未登録"))) | F4: =IF($C4="","",IF($B4="YM",IFERROR(INDEX(機種マスタ!$K$4:$K$203,MATCH($C4,機種マスタ!$J$4:$J$203,0)),"-"),IFERROR(INDEX(機種マスタ!$C$4:$C$363,MATCH($C4,機種マスタ!$B$4:$B$363,0)),"-"))) | G4: =IF($C4="","",IF($B4="YM",IFERROR(N(INDEX(機種マスタ!$L$4:$L$203,MATCH($C4,機種マスタ!$J$4:$J$203,0))),0),IFERROR(N(INDEX(機種マスタ!$D$4:$D$363,MATCH($C4,機種マスタ!$B$4:$B$363,0))),0))) | H4: =IF($C4="","",IF($D4="",1,$D4)) | I4: =IF($C4="","",IF(G4>0,(G4+IFERROR(VLOOKUP(F4,機種マスタ!$Q$4:$R$6,2,FALSE),0))*H4,0)) | K4: 戦略対象機種 販売台数 | L4: =SUMIFS(H4:H503,G4:G503,">0")
A5: 46296 | B5: SB | C5: motorola razr 60s | E5: =IF($C5="","",IF($B5="YM",IFERROR(INDEX(機種マスタ!$I$4:$I$203,MATCH($C5,機種マスタ!$J$4:$J$203,0)),"未登録"),IFERROR(INDEX(機種マスタ!$A$4:$A$363,MATCH($C5,機種マスタ!$B$4:$B$363,0)),"未登録"))) | F5: =IF($C5="","",IF($B5="YM",IFERROR(INDEX(機種マスタ!$K$4:$K$203,MATCH($C5,機種マスタ!$J$4:$J$203,0)),"-"),IFERROR(INDEX(機種マスタ!$C$4:$C$363,MATCH($C5,機種マスタ!$B$4:$B$363,0)),"-"))) | G5: =IF($C5="","",IF($B5="YM",IFERROR(N(INDEX(機種マスタ!$L$4:$L$203,MATCH($C5,機種マスタ!$J$4:$J$203,0))),0),IFERROR(N(INDEX(機種マスタ!$D$4:$D$363,MATCH($C5,機種マスタ!$B$4:$B$363,0))),0))) | H5: =IF($C5="","",IF($D5="",1,$D5)) | I5: =IF($C5="","",IF(G5>0,(G5+IFERROR(VLOOKUP(F5,機種マスタ!$Q$4:$R$6,2,FALSE),0))*H5,0)) | K5: 全販売台数 | L5: =SUM(H4:H503)
A6: 46296 | B6: SB | C6: moto g37 | E6: =IF($C6="","",IF($B6="YM",IFERROR(INDEX(機種マスタ!$I$4:$I$203,MATCH($C6,機種マスタ!$J$4:$J$203,0)),"未登録"),IFERROR(INDEX(機種マスタ!$A$4:$A$363,MATCH($C6,機種マスタ!$B$4:$B$363,0)),"未登録"))) | F6: =IF($C6="","",IF($B6="YM",IFERROR(INDEX(機種マスタ!$K$4:$K$203,MATCH($C6,機種マスタ!$J$4:$J$203,0)),"-"),IFERROR(INDEX(機種マスタ!$C$4:$C$363,MATCH($C6,機種マスタ!$B$4:$B$363,0)),"-"))) | G6: =IF($C6="","",IF($B6="YM",IFERROR(N(INDEX(機種マスタ!$L$4:$L$203,MATCH($C6,機種マスタ!$J$4:$J$203,0))),0),IFERROR(N(INDEX(機種マスタ!$D$4:$D$363,MATCH($C6,機種マスタ!$B$4:$B$363,0))),0))) | H6: =IF($C6="","",IF($D6="",1,$D6)) | I6: =IF($C6="","",IF(G6>0,(G6+IFERROR(VLOOKUP(F6,機種マスタ!$Q$4:$R$6,2,FALSE),0))*H6,0)) | K6: 販売日 未入力 の行数 | L6: =SUMPRODUCT((C4:C503<>"")*(A4:A503=""))
A7: 46297 | B7: SB | C7: AQUOS wish6 | E7: =IF($C7="","",IF($B7="YM",IFERROR(INDEX(機種マスタ!$I$4:$I$203,MATCH($C7,機種マスタ!$J$4:$J$203,0)),"未登録"),IFERROR(INDEX(機種マスタ!$A$4:$A$363,MATCH($C7,機種マスタ!$B$4:$B$363,0)),"未登録"))) | F7: =IF($C7="","",IF($B7="YM",IFERROR(INDEX(機種マスタ!$K$4:$K$203,MATCH($C7,機種マスタ!$J$4:$J$203,0)),"-"),IFERROR(INDEX(機種マスタ!$C$4:$C$363,MATCH($C7,機種マスタ!$B$4:$B$363,0)),"-"))) | G7: =IF($C7="","",IF($B7="YM",IFERROR(N(INDEX(機種マスタ!$L$4:$L$203,MATCH($C7,機種マスタ!$J$4:$J$203,0))),0),IFERROR(N(INDEX(機種マスタ!$D$4:$D$363,MATCH($C7,機種マスタ!$B$4:$B$363,0))),0))) | H7: =IF($C7="","",IF($D7="",1,$D7)) | I7: =IF($C7="","",IF(G7>0,(G7+IFERROR(VLOOKUP(F7,機種マスタ!$Q$4:$R$6,2,FALSE),0))*H7,0))
A8: 46297 | B8: SB | C8: iPhone 17(256GB) | E8: =IF($C8="","",IF($B8="YM",IFERROR(INDEX(機種マスタ!$I$4:$I$203,MATCH($C8,機種マスタ!$J$4:$J$203,0)),"未登録"),IFERROR(INDEX(機種マスタ!$A$4:$A$363,MATCH($C8,機種マスタ!$B$4:$B$363,0)),"未登録"))) | F8: =IF($C8="","",IF($B8="YM",IFERROR(INDEX(機種マスタ!$K$4:$K$203,MATCH($C8,機種マスタ!$J$4:$J$203,0)),"-"),IFERROR(INDEX(機種マスタ!$C$4:$C$363,MATCH($C8,機種マスタ!$B$4:$B$363,0)),"-"))) | G8: =IF($C8="","",IF($B8="YM",IFERROR(N(INDEX(機種マスタ!$L$4:$L$203,MATCH($C8,機種マスタ!$J$4:$J$203,0))),0),IFERROR(N(INDEX(機種マスタ!$D$4:$D$363,MATCH($C8,機種マスタ!$B$4:$B$363,0))),0))) | H8: =IF($C8="","",IF($D8="",1,$D8)) | I8: =IF($C8="","",IF(G8>0,(G8+IFERROR(VLOOKUP(F8,機種マスタ!$Q$4:$R$6,2,FALSE),0))*H8,0))
A9: 46298 | B9: SB | C9: Samsung Galaxy S26(256GB) | E9: =IF($C9="","",IF($B9="YM",IFERROR(INDEX(機種マスタ!$I$4:$I$203,MATCH($C9,機種マスタ!$J$4:$J$203,0)),"未登録"),IFERROR(INDEX(機種マスタ!$A$4:$A$363,MATCH($C9,機種マスタ!$B$4:$B$363,0)),"未登録"))) | F9: =IF($C9="","",IF($B9="YM",IFERROR(INDEX(機種マスタ!$K$4:$K$203,MATCH($C9,機種マスタ!$J$4:$J$203,0)),"-"),IFERROR(INDEX(機種マスタ!$C$4:$C$363,MATCH($C9,機種マスタ!$B$4:$B$363,0)),"-"))) | G9: =IF($C9="","",IF($B9="YM",IFERROR(N(INDEX(機種マスタ!$L$4:$L$203,MATCH($C9,機種マスタ!$J$4:$J$203,0))),0),IFERROR(N(INDEX(機種マスタ!$D$4:$D$363,MATCH($C9,機種マスタ!$B$4:$B$363,0))),0))) | H9: =IF($C9="","",IF($D9="",1,$D9)) | I9: =IF($C9="","",IF(G9>0,(G9+IFERROR(VLOOKUP(F9,機種マスタ!$Q$4:$R$6,2,FALSE),0))*H9,0))
A10: 46298 | B10: SB | C10: motorola edge 60s pro | E10: =IF($C10="","",IF($B10="YM",IFERROR(INDEX(機種マスタ!$I$4:$I$203,MATCH($C10,機種マスタ!$J$4:$J$203,0)),"未登録"),IFERROR(INDEX(機種マスタ!$A$4:$A$363,MATCH($C10,機種マスタ!$B$4:$B$363,0)),"未登録"))) | F10: =IF($C10="","",IF($B10="YM",IFERROR(INDEX(機種マスタ!$K$4:$K$203,MATCH($C10,機種マスタ!$J$4:$J$203,0)),"-"),IFERROR(INDEX(機種マスタ!$C$4:$C$363,MATCH($C10,機種マスタ!$B$4:$B$363,0)),"-"))) | G10: =IF($C10="","",IF($B10="YM",IFERROR(N(INDEX(機種マスタ!$L$4:$L$203,MATCH($C10,機種マスタ!$J$4:$J$203,0))),0),IFERROR(N(INDEX(機種マスタ!$D$4:$D$363,MATCH($C10,機種マスタ!$B$4:$B$363,0))),0))) | H10: =IF($C10="","",IF($D10="",1,$D10)) | I10: =IF($C10="","",IF(G10>0,(G10+IFERROR(VLOOKUP(F10,機種マスタ!$Q$4:$R$6,2,FALSE),0))*H10,0))
A11: 46298 | B11: SB | C11: Samsung Galaxy S26+(512GB) | E11: =IF($C11="","",IF($B11="YM",IFERROR(INDEX(機種マスタ!$I$4:$I$203,MATCH($C11,機種マスタ!$J$4:$J$203,0)),"未登録"),IFERROR(INDEX(機種マスタ!$A$4:$A$363,MATCH($C11,機種マスタ!$B$4:$B$363,0)),"未登録"))) | F11: =IF($C11="","",IF($B11="YM",IFERROR(INDEX(機種マスタ!$K$4:$K$203,MATCH($C11,機種マスタ!$J$4:$J$203,0)),"-"),IFERROR(INDEX(機種マスタ!$C$4:$C$363,MATCH($C11,機種マスタ!$B$4:$B$363,0)),"-"))) | G11: =IF($C11="","",IF($B11="YM",IFERROR(N(INDEX(機種マスタ!$L$4:$L$203,MATCH($C11,機種マスタ!$J$4:$J$203,0))),0),IFERROR(N(INDEX(機種マスタ!$D$4:$D$363,MATCH($C11,機種マスタ!$B$4:$B$363,0))),0))) | H11: =IF($C11="","",IF($D11="",1,$D11)) | I11: =IF($C11="","",IF(G11>0,(G11+IFERROR(VLOOKUP(F11,機種マスタ!$Q$4:$R$6,2,FALSE),0))*H11,0))
A12: 46299 | B12: SB | C12: iPhone 18 Pro(512GB) | E12: =IF($C12="","",IF($B12="YM",IFERROR(INDEX(機種マスタ!$I$4:$I$203,MATCH($C12,機種マスタ!$J$4:$J$203,0)),"未登録"),IFERROR(INDEX(機種マスタ!$A$4:$A$363,MATCH($C12,機種マスタ!$B$4:$B$363,0)),"未登録"))) | F12: =IF($C12="","",IF($B12="YM",IFERROR(INDEX(機種マスタ!$K$4:$K$203,MATCH($C12,機種マスタ!$J$4:$J$203,0)),"-"),IFERROR(INDEX(機種マスタ!$C$4:$C$363,MATCH($C12,機種マスタ!$B$4:$B$363,0)),"-"))) | G12: =IF($C12="","",IF($B12="YM",IFERROR(N(INDEX(機種マスタ!$L$4:$L$203,MATCH($C12,機種マスタ!$J$4:$J$203,0))),0),IFERROR(N(INDEX(機種マスタ!$D$4:$D$363,MATCH($C12,機種マスタ!$B$4:$B$363,0))),0))) | H12: =IF($C12="","",IF($D12="",1,$D12)) | I12: =IF($C12="","",IF(G12>0,(G12+IFERROR(VLOOKUP(F12,機種マスタ!$Q$4:$R$6,2,FALSE),0))*H12,0))
A13: 46299 | B13: SB | C13: iPhone 18 Pro Max(512GB) | E13: =IF($C13="","",IF($B13="YM",IFERROR(INDEX(機種マスタ!$I$4:$I$203,MATCH($C13,機種マスタ!$J$4:$J$203,0)),"未登録"),IFERROR(INDEX(機種マスタ!$A$4:$A$363,MATCH($C13,機種マスタ!$B$4:$B$363,0)),"未登録"))) | F13: =IF($C13="","",IF($B13="YM",IFERROR(INDEX(機種マスタ!$K$4:$K$203,MATCH($C13,機種マスタ!$J$4:$J$203,0)),"-"),IFERROR(INDEX(機種マスタ!$C$4:$C$363,MATCH($C13,機種マスタ!$B$4:$B$363,0)),"-"))) | G13: =IF($C13="","",IF($B13="YM",IFERROR(N(INDEX(機種マスタ!$L$4:$L$203,MATCH($C13,機種マスタ!$J$4:$J$203,0))),0),IFERROR(N(INDEX(機種マスタ!$D$4:$D$363,MATCH($C13,機種マスタ!$B$4:$B$363,0))),0))) | H13: =IF($C13="","",IF($D13="",1,$D13)) | I13: =IF($C13="","",IF(G13>0,(G13+IFERROR(VLOOKUP(F13,機種マスタ!$Q$4:$R$6,2,FALSE),0))*H13,0))
A14: 46299 | B14: SB | C14: iPhone 18 Pro Max(256GB) | E14: =IF($C14="","",IF($B14="YM",IFERROR(INDEX(機種マスタ!$I$4:$I$203,MATCH($C14,機種マスタ!$J$4:$J$203,0)),"未登録"),IFERROR(INDEX(機種マスタ!$A$4:$A$363,MATCH($C14,機種マスタ!$B$4:$B$363,0)),"未登録"))) | F14: =IF($C14="","",IF($B14="YM",IFERROR(INDEX(機種マスタ!$K$4:$K$203,MATCH($C14,機種マスタ!$J$4:$J$203,0)),"-"),IFERROR(INDEX(機種マスタ!$C$4:$C$363,MATCH($C14,機種マスタ!$B$4:$B$363,0)),"-"))) | G14: =IF($C14="","",IF($B14="YM",IFERROR(N(INDEX(機種マスタ!$L$4:$L$203,MATCH($C14,機種マスタ!$J$4:$J$203,0))),0),IFERROR(N(INDEX(機種マスタ!$D$4:$D$363,MATCH($C14,機種マスタ!$B$4:$B$363,0))),0))) | H14: =IF($C14="","",IF($D14="",1,$D14)) | I14: =IF($C14="","",IF(G14>0,(G14+IFERROR(VLOOKUP(F14,機種マスタ!$Q$4:$R$6,2,FALSE),0))*H14,0))
A15: 46299 | B15: SB | C15: iPhone 18 Pro(256GB) | E15: =IF($C15="","",IF($B15="YM",IFERROR(INDEX(機種マスタ!$I$4:$I$203,MATCH($C15,機種マスタ!$J$4:$J$203,0)),"未登録"),IFERROR(INDEX(機種マスタ!$A$4:$A$363,MATCH($C15,機種マスタ!$B$4:$B$363,0)),"未登録"))) | F15: =IF($C15="","",IF($B15="YM",IFERROR(INDEX(機種マスタ!$K$4:$K$203,MATCH($C15,機種マスタ!$J$4:$J$203,0)),"-"),IFERROR(INDEX(機種マスタ!$C$4:$C$363,MATCH($C15,機種マスタ!$B$4:$B$363,0)),"-"))) | G15: =IF($C15="","",IF($B15="YM",IFERROR(N(INDEX(機種マスタ!$L$4:$L$203,MATCH($C15,機種マスタ!$J$4:$J$203,0))),0),IFERROR(N(INDEX(機種マスタ!$D$4:$D$363,MATCH($C15,機種マスタ!$B$4:$B$363,0))),0))) | H15: =IF($C15="","",IF($D15="",1,$D15)) | I15: =IF($C15="","",IF(G15>0,(G15+IFERROR(VLOOKUP(F15,機種マスタ!$Q$4:$R$6,2,FALSE),0))*H15,0))
A16: 46299 | B16: SB | C16: iPhone 17(256GB) | E16: =IF($C16="","",IF($B16="YM",IFERROR(INDEX(機種マスタ!$I$4:$I$203,MATCH($C16,機種マスタ!$J$4:$J$203,0)),"未登録"),IFERROR(INDEX(機種マスタ!$A$4:$A$363,MATCH($C16,機種マスタ!$B$4:$B$363,0)),"未登録"))) | F16: =IF($C16="","",IF($B16="YM",IFERROR(INDEX(機種マスタ!$K$4:$K$203,MATCH($C16,機種マスタ!$J$4:$J$203,0)),"-"),IFERROR(INDEX(機種マスタ!$C$4:$C$363,MATCH($C16,機種マスタ!$B$4:$B$363,0)),"-"))) | G16: =IF($C16="","",IF($B16="YM",IFERROR(N(INDEX(機種マスタ!$L$4:$L$203,MATCH($C16,機種マスタ!$J$4:$J$203,0))),0),IFERROR(N(INDEX(機種マスタ!$D$4:$D$363,MATCH($C16,機種マスタ!$B$4:$B$363,0))),0))) | H16: =IF($C16="","",IF($D16="",1,$D16)) | I16: =IF($C16="","",IF(G16>0,(G16+IFERROR(VLOOKUP(F16,機種マスタ!$Q$4:$R$6,2,FALSE),0))*H16,0))
A17: 46299 | B17: SB | C17: iPhone 17(256GB) | E17: =IF($C17="","",IF($B17="YM",IFERROR(INDEX(機種マスタ!$I$4:$I$203,MATCH($C17,機種マスタ!$J$4:$J$203,0)),"未登録"),IFERROR(INDEX(機種マスタ!$A$4:$A$363,MATCH($C17,機種マスタ!$B$4:$B$363,0)),"未登録"))) | F17: =IF($C17="","",IF($B17="YM",IFERROR(INDEX(機種マスタ!$K$4:$K$203,MATCH($C17,機種マスタ!$J$4:$J$203,0)),"-"),IFERROR(INDEX(機種マスタ!$C$4:$C$363,MATCH($C17,機種マスタ!$B$4:$B$363,0)),"-"))) | G17: =IF($C17="","",IF($B17="YM",IFERROR(N(INDEX(機種マスタ!$L$4:$L$203,MATCH($C17,機種マスタ!$J$4:$J$203,0))),0),IFERROR(N(INDEX(機種マスタ!$D$4:$D$363,MATCH($C17,機種マスタ!$B$4:$B$363,0))),0))) | H17: =IF($C17="","",IF($D17="",1,$D17)) | I17: =IF($C17="","",IF(G17>0,(G17+IFERROR(VLOOKUP(F17,機種マスタ!$Q$4:$R$6,2,FALSE),0))*H17,0))
A18: 46299 | B18: SB | C18: iPhone 17(256GB) | E18: =IF($C18="","",IF($B18="YM",IFERROR(INDEX(機種マスタ!$I$4:$I$203,MATCH($C18,機種マスタ!$J$4:$J$203,0)),"未登録"),IFERROR(INDEX(機種マスタ!$A$4:$A$363,MATCH($C18,機種マスタ!$B$4:$B$363,0)),"未登録"))) | F18: =IF($C18="","",IF($B18="YM",IFERROR(INDEX(機種マスタ!$K$4:$K$203,MATCH($C18,機種マスタ!$J$4:$J$203,0)),"-"),IFERROR(INDEX(機種マスタ!$C$4:$C$363,MATCH($C18,機種マスタ!$B$4:$B$363,0)),"-"))) | G18: =IF($C18="","",IF($B18="YM",IFERROR(N(INDEX(機種マスタ!$L$4:$L$203,MATCH($C18,機種マスタ!$J$4:$J$203,0))),0),IFERROR(N(INDEX(機種マスタ!$D$4:$D$363,MATCH($C18,機種マスタ!$B$4:$B$363,0))),0))) | H18: =IF($C18="","",IF($D18="",1,$D18)) | I18: =IF($C18="","",IF(G18>0,(G18+IFERROR(VLOOKUP(F18,機種マスタ!$Q$4:$R$6,2,FALSE),0))*H18,0))
... A26: 46302 | B26: SB | C26: Samsung Galaxy A57 5G | E26: =IF($C26="","",IF($B26="YM",IFERROR(INDEX(機種マスタ!$I$4:$I$203,MATCH($C26,機種マスタ!$J$4:$J$203,0)),"未登録"),IFERROR(INDEX(機種マスタ!$A$4:$A$363,MATCH($C26,機種マスタ!$B$4:$B$363,0)),"未登録"))) | F26: =IF($C26="","",IF($B26="YM",IFERROR(INDEX(機種マスタ!$K$4:$K$203,MATCH($C26,機種マスタ!$J$4:$J$203,0)),"-"),IFERROR(INDEX(機種マスタ!$C$4:$C$363,MATCH($C26,機種マスタ!$B$4:$B$363,0)),"-"))) | G26: =IF($C26="","",IF($B26="YM",IFERROR(N(INDEX(機種マスタ!$L$4:$L$203,MATCH($C26,機種マスタ!$J$4:$J$203,0))),0),IFERROR(N(INDEX(機種マスタ!$D$4:$D$363,MATCH($C26,機種マスタ!$B$4:$B$363,0))),0))) | H26: =IF($C26="","",IF($D26="",1,$D26)) | I26: =IF($C26="","",IF(G26>0,(G26+IFERROR(VLOOKUP(F26,機種マスタ!$Q$4:$R$6,2,FALSE),0))*H26,0))
E27: =IF($C27="","",IF($B27="YM",IFERROR(INDEX(機種マスタ!$I$4:$I$203,MATCH($C27,機種マスタ!$J$4:$J$203,0)),"未登録"),IFERROR(INDEX(機種マスタ!$A$4:$A$363,MATCH($C27,機種マスタ!$B$4:$B$363,0)),"未登録"))) | F27: =IF($C27="","",IF($B27="YM",IFERROR(INDEX(機種マスタ!$K$4:$K$203,MATCH($C27,機種マスタ!$J$4:$J$203,0)),"-"),IFERROR(INDEX(機種マスタ!$C$4:$C$363,MATCH($C27,機種マスタ!$B$4:$B$363,0)),"-"))) | G27: =IF($C27="","",IF($B27="YM",IFERROR(N(INDEX(機種マスタ!$L$4:$L$203,MATCH($C27,機種マスタ!$J$4:$J$203,0))),0),IFERROR(N(INDEX(機種マスタ!$D$4:$D$363,MATCH($C27,機種マスタ!$B$4:$B$363,0))),0))) | H27: =IF($C27="","",IF($D27="",1,$D27)) | I27: =IF($C27="","",IF(G27>0,(G27+IFERROR(VLOOKUP(F27,機種マスタ!$Q$4:$R$6,2,FALSE),0))*H27,0))
E28: =IF($C28="","",IF($B28="YM",IFERROR(INDEX(機種マスタ!$I$4:$I$203,MATCH($C28,機種マスタ!$J$4:$J$203,0)),"未登録"),IFERROR(INDEX(機種マスタ!$A$4:$A$363,MATCH($C28,機種マスタ!$B$4:$B$363,0)),"未登録"))) | F28: =IF($C28="","",IF($B28="YM",IFERROR(INDEX(機種マスタ!$K$4:$K$203,MATCH($C28,機種マスタ!$J$4:$J$203,0)),"-"),IFERROR(INDEX(機種マスタ!$C$4:$C$363,MATCH($C28,機種マスタ!$B$4:$B$363,0)),"-"))) | G28: =IF($C28="","",IF($B28="YM",IFERROR(N(INDEX(機種マスタ!$L$4:$L$203,MATCH($C28,機種マスタ!$J$4:$J$203,0))),0),IFERROR(N(INDEX(機種マスタ!$D$4:$D$363,MATCH($C28,機種マスタ!$B$4:$B$363,0))),0))) | H28: =IF($C28="","",IF($D28="",1,$D28)) | I28: =IF($C28="","",IF(G28>0,(G28+IFERROR(VLOOKUP(F28,機種マスタ!$Q$4:$R$6,2,FALSE),0))*H28,0))
E29: =IF($C29="","",IF($B29="YM",IFERROR(INDEX(機種マスタ!$I$4:$I$203,MATCH($C29,機種マスタ!$J$4:$J$203,0)),"未登録"),IFERROR(INDEX(機種マスタ!$A$4:$A$363,MATCH($C29,機種マスタ!$B$4:$B$363,0)),"未登録"))) | F29: =IF($C29="","",IF($B29="YM",IFERROR(INDEX(機種マスタ!$K$4:$K$203,MATCH($C29,機種マスタ!$J$4:$J$203,0)),"-"),IFERROR(INDEX(機種マスタ!$C$4:$C$363,MATCH($C29,機種マスタ!$B$4:$B$363,0)),"-"))) | G29: =IF($C29="","",IF($B29="YM",IFERROR(N(INDEX(機種マスタ!$L$4:$L$203,MATCH($C29,機種マスタ!$J$4:$J$203,0))),0),IFERROR(N(INDEX(機種マスタ!$D$4:$D$363,MATCH($C29,機種マスタ!$B$4:$B$363,0))),0))) | H29: =IF($C29="","",IF($D29="",1,$D29)) | I29: =IF($C29="","",IF(G29>0,(G29+IFERROR(VLOOKUP(F29,機種マスタ!$Q$4:$R$6,2,FALSE),0))*H29,0))
E30: =IF($C30="","",IF($B30="YM",IFERROR(INDEX(機種マスタ!$I$4:$I$203,MATCH($C30,機種マスタ!$J$4:$J$203,0)),"未登録"),IFERROR(INDEX(機種マスタ!$A$4:$A$363,MATCH($C30,機種マスタ!$B$4:$B$363,0)),"未登録"))) | F30: =IF($C30="","",IF($B30="YM",IFERROR(INDEX(機種マスタ!$K$4:$K$203,MATCH($C30,機種マスタ!$J$4:$J$203,0)),"-"),IFERROR(INDEX(機種マスタ!$C$4:$C$363,MATCH($C30,機種マスタ!$B$4:$B$363,0)),"-"))) | G30: =IF($C30="","",IF($B30="YM",IFERROR(N(INDEX(機種マスタ!$L$4:$L$203,MATCH($C30,機種マスタ!$J$4:$J$203,0))),0),IFERROR(N(INDEX(機種マスタ!$D$4:$D$363,MATCH($C30,機種マスタ!$B$4:$B$363,0))),0))) | H30: =IF($C30="","",IF($D30="",1,$D30)) | I30: =IF($C30="","",IF(G30>0,(G30+IFERROR(VLOOKUP(F30,機種マスタ!$Q$4:$R$6,2,FALSE),0))*H30,0))
E31: =IF($C31="","",IF($B31="YM",IFERROR(INDEX(機種マスタ!$I$4:$I$203,MATCH($C31,機種マスタ!$J$4:$J$203,0)),"未登録"),IFERROR(INDEX(機種マスタ!$A$4:$A$363,MATCH($C31,機種マスタ!$B$4:$B$363,0)),"未登録"))) | F31: =IF($C31="","",IF($B31="YM",IFERROR(INDEX(機種マスタ!$K$4:$K$203,MATCH($C31,機種マスタ!$J$4:$J$203,0)),"-"),IFERROR(INDEX(機種マスタ!$C$4:$C$363,MATCH($C31,機種マスタ!$B$4:$B$363,0)),"-"))) | G31: =IF($C31="","",IF($B31="YM",IFERROR(N(INDEX(機種マスタ!$L$4:$L$203,MATCH($C31,機種マスタ!$J$4:$J$203,0))),0),IFERROR(N(INDEX(機種マスタ!$D$4:$D$363,MATCH($C31,機種マスタ!$B$4:$B$363,0))),0))) | H31: =IF($C31="","",IF($D31="",1,$D31)) | I31: =IF($C31="","",IF(G31>0,(G31+IFERROR(VLOOKUP(F31,機種マスタ!$Q$4:$R$6,2,FALSE),0))*H31,0))
E32: =IF($C32="","",IF($B32="YM",IFERROR(INDEX(機種マスタ!$I$4:$I$203,MATCH($C32,機種マスタ!$J$4:$J$203,0)),"未登録"),IFERROR(INDEX(機種マスタ!$A$4:$A$363,MATCH($C32,機種マスタ!$B$4:$B$363,0)),"未登録"))) | F32: =IF($C32="","",IF($B32="YM",IFERROR(INDEX(機種マスタ!$K$4:$K$203,MATCH($C32,機種マスタ!$J$4:$J$203,0)),"-"),IFERROR(INDEX(機種マスタ!$C$4:$C$363,MATCH($C32,機種マスタ!$B$4:$B$363,0)),"-"))) | G32: =IF($C32="","",IF($B32="YM",IFERROR(N(INDEX(機種マスタ!$L$4:$L$203,MATCH($C32,機種マスタ!$J$4:$J$203,0))),0),IFERROR(N(INDEX(機種マスタ!$D$4:$D$363,MATCH($C32,機種マスタ!$B$4:$B$363,0))),0))) | H32: =IF($C32="","",IF($D32="",1,$D32)) | I32: =IF($C32="","",IF(G32>0,(G32+IFERROR(VLOOKUP(F32,機種マスタ!$Q$4:$R$6,2,FALSE),0))*H32,0))
E33: =IF($C33="","",IF($B33="YM",IFERROR(INDEX(機種マスタ!$I$4:$I$203,MATCH($C33,機種マスタ!$J$4:$J$203,0)),"未登録"),IFERROR(INDEX(機種マスタ!$A$4:$A$363,MATCH($C33,機種マスタ!$B$4:$B$363,0)),"未登録"))) | F33: =IF($C33="","",IF($B33="YM",IFERROR(INDEX(機種マスタ!$K$4:$K$203,MATCH($C33,機種マスタ!$J$4:$J$203,0)),"-"),IFERROR(INDEX(機種マスタ!$C$4:$C$363,MATCH($C33,機種マスタ!$B$4:$B$363,0)),"-"))) | G33: =IF($C33="","",IF($B33="YM",IFERROR(N(INDEX(機種マスタ!$L$4:$L$203,MATCH($C33,機種マスタ!$J$4:$J$203,0))),0),IFERROR(N(INDEX(機種マスタ!$D$4:$D$363,MATCH($C33,機種マスタ!$B$4:$B$363,0))),0))) | H33: =IF($C33="","",IF($D33="",1,$D33)) | I33: =IF($C33="","",IF(G33>0,(G33+IFERROR(VLOOKUP(F33,機種マスタ!$Q$4:$R$6,2,FALSE),0))*H33,0))
E34: =IF($C34="","",IF($B34="YM",IFERROR(INDEX(機種マスタ!$I$4:$I$203,MATCH($C34,機種マスタ!$J$4:$J$203,0)),"未登録"),IFERROR(INDEX(機種マスタ!$A$4:$A$363,MATCH($C34,機種マスタ!$B$4:$B$363,0)),"未登録"))) | F34: =IF($C34="","",IF($B34="YM",IFERROR(INDEX(機種マスタ!$K$4:$K$203,MATCH($C34,機種マスタ!$J$4:$J$203,0)),"-"),IFERROR(INDEX(機種マスタ!$C$4:$C$363,MATCH($C34,機種マスタ!$B$4:$B$363,0)),"-"))) | G34: =IF($C34="","",IF($B34="YM",IFERROR(N(INDEX(機種マスタ!$L$4:$L$203,MATCH($C34,機種マスタ!$J$4:$J$203,0))),0),IFERROR(N(INDEX(機種マスタ!$D$4:$D$363,MATCH($C34,機種マスタ!$B$4:$B$363,0))),0))) | H34: =IF($C34="","",IF($D34="",1,$D34)) | I34: =IF($C34="","",IF(G34>0,(G34+IFERROR(VLOOKUP(F34,機種マスタ!$Q$4:$R$6,2,FALSE),0))*H34,0))
E35: =IF($C35="","",IF($B35="YM",IFERROR(INDEX(機種マスタ!$I$4:$I$203,MATCH($C35,機種マスタ!$J$4:$J$203,0)),"未登録"),IFERROR(INDEX(機種マスタ!$A$4:$A$363,MATCH($C35,機種マスタ!$B$4:$B$363,0)),"未登録"))) | F35: =IF($C35="","",IF($B35="YM",IFERROR(INDEX(機種マスタ!$K$4:$K$203,MATCH($C35,機種マスタ!$J$4:$J$203,0)),"-"),IFERROR(INDEX(機種マスタ!$C$4:$C$363,MATCH($C35,機種マスタ!$B$4:$B$363,0)),"-"))) | G35: =IF($C35="","",IF($B35="YM",IFERROR(N(INDEX(機種マスタ!$L$4:$L$203,MATCH($C35,機種マスタ!$J$4:$J$203,0))),0),IFERROR(N(INDEX(機種マスタ!$D$4:$D$363,MATCH($C35,機種マスタ!$B$4:$B$363,0))),0))) | H35: =IF($C35="","",IF($D35="",1,$D35)) | I35: =IF($C35="","",IF(G35>0,(G35+IFERROR(VLOOKUP(F35,機種マスタ!$Q$4:$R$6,2,FALSE),0))*H35,0))
E36: =IF($C36="","",IF($B36="YM",IFERROR(INDEX(機種マスタ!$I$4:$I$203,MATCH($C36,機種マスタ!$J$4:$J$203,0)),"未登録"),IFERROR(INDEX(機種マスタ!$A$4:$A$363,MATCH($C36,機種マスタ!$B$4:$B$363,0)),"未登録"))) | F36: =IF($C36="","",IF($B36="YM",IFERROR(INDEX(機種マスタ!$K$4:$K$203,MATCH($C36,機種マスタ!$J$4:$J$203,0)),"-"),IFERROR(INDEX(機種マスタ!$C$4:$C$363,MATCH($C36,機種マスタ!$B$4:$B$363,0)),"-"))) | G36: =IF($C36="","",IF($B36="YM",IFERROR(N(INDEX(機種マスタ!$L$4:$L$203,MATCH($C36,機種マスタ!$J$4:$J$203,0))),0),IFERROR(N(INDEX(機種マスタ!$D$4:$D$363,MATCH($C36,機種マスタ!$B$4:$B$363,0))),0))) | H36: =IF($C36="","",IF($D36="",1,$D36)) | I36: =IF($C36="","",IF(G36>0,(G36+IFERROR(VLOOKUP(F36,機種マスタ!$Q$4:$R$6,2,FALSE),0))*H36,0))
E37: =IF($C37="","",IF($B37="YM",IFERROR(INDEX(機種マスタ!$I$4:$I$203,MATCH($C37,機種マスタ!$J$4:$J$203,0)),"未登録"),IFERROR(INDEX(機種マスタ!$A$4:$A$363,MATCH($C37,機種マスタ!$B$4:$B$363,0)),"未登録"))) | F37: =IF($C37="","",IF($B37="YM",IFERROR(INDEX(機種マスタ!$K$4:$K$203,MATCH($C37,機種マスタ!$J$4:$J$203,0)),"-"),IFERROR(INDEX(機種マスタ!$C$4:$C$363,MATCH($C37,機種マスタ!$B$4:$B$363,0)),"-"))) | G37: =IF($C37="","",IF($B37="YM",IFERROR(N(INDEX(機種マスタ!$L$4:$L$203,MATCH($C37,機種マスタ!$J$4:$J$203,0))),0),IFERROR(N(INDEX(機種マスタ!$D$4:$D$363,MATCH($C37,機種マスタ!$B$4:$B$363,0))),0))) | H37: =IF($C37="","",IF($D37="",1,$D37)) | I37: =IF($C37="","",IF(G37>0,(G37+IFERROR(VLOOKUP(F37,機種マスタ!$Q$4:$R$6,2,FALSE),0))*H37,0))
E38: =IF($C38="","",IF($B38="YM",IFERROR(INDEX(機種マスタ!$I$4:$I$203,MATCH($C38,機種マスタ!$J$4:$J$203,0)),"未登録"),IFERROR(INDEX(機種マスタ!$A$4:$A$363,MATCH($C38,機種マスタ!$B$4:$B$363,0)),"未登録"))) | F38: =IF($C38="","",IF($B38="YM",IFERROR(INDEX(機種マスタ!$K$4:$K$203,MATCH($C38,機種マスタ!$J$4:$J$203,0)),"-"),IFERROR(INDEX(機種マスタ!$C$4:$C$363,MATCH($C38,機種マスタ!$B$4:$B$363,0)),"-"))) | G38: =IF($C38="","",IF($B38="YM",IFERROR(N(INDEX(機種マスタ!$L$4:$L$203,MATCH($C38,機種マスタ!$J$4:$J$203,0))),0),IFERROR(N(INDEX(機種マスタ!$D$4:$D$363,MATCH($C38,機種マスタ!$B$4:$B$363,0))),0))) | H38: =IF($C38="","",IF($D38="",1,$D38)) | I38: =IF($C38="","",IF(G38>0,(G38+IFERROR(VLOOKUP(F38,機種マスタ!$Q$4:$R$6,2,FALSE),0))*H38,0))
... E503: =IF($C503="","",IF($B503="YM",IFERROR(INDEX(機種マスタ!$I$4:$I$203,MATCH($C503,機種マスタ!$J$4:$J$203,0)),"未登録"),IFERROR(INDEX(機種マスタ!$A$4:$A$363,MATCH($C503,機種マスタ!$B$4:$B$363,0)),"未登録"))) | F503: =IF($C503="","",IF($B503="YM",IFERROR(INDEX(機種マスタ!$K$4:$K$203,MATCH($C503,機種マスタ!$J$4:$J$203,0)),"-"),IFERROR(INDEX(機種マスタ!$C$4:$C$363,MATCH($C503,機種マスタ!$B$4:$B$363,0)),"-"))) | G503: =IF($C503="","",IF($B503="YM",IFERROR(N(INDEX(機種マスタ!$L$4:$L$203,MATCH($C503,機種マスタ!$J$4:$J$203,0))),0),IFERROR(N(INDEX(機種マスタ!$D$4:$D$363,MATCH($C503,機種マスタ!$B$4:$B$363,0))),0))) | H503: =IF($C503="","",IF($D503="",1,$D503)) | I503: =IF($C503="","",IF(G503>0,(G503+IFERROR(VLOOKUP(F503,機種マスタ!$Q$4:$R$6,2,FALSE),0))*H503,0))

Sheet 機種マスタ
A1: 機種マスタ(対象機種と戦略Pt)
A2: 「機種Pt」シートのSB機種(左)とYM機種(右)を登録しています。機種の追加・戦略Ptの変更は黄色いセルを編集してください(戦略Ptが空欄の機種は加算されません)。機種Ptの点数(H/M/L)は右端のQ〜R列で変更できます。SBとYMで同じ機種名がある場合は、機種販売入力で区分(SB/YM)を選びます。
A3: カテゴリ | B3: SB機種名 | C3: 機種Pt | D3: 戦略Pt (1台あたり) | E3: 販売台数 | F3: 獲得戦略Pt | G3: エンディング 予定日 | I3: カテゴリ | J3: YM機種名 | K3: 機種Pt | L3: 戦略Pt (1台あたり) | M3: 販売台数 | N3: 獲得戦略Pt | O3: エンディング 予定日 | Q3: 機種Pt | R3: 点数
A4: iPhone | B4: iPhone 18 Pro(256GB) | C4: H | D4: 2 | E4: =IF($B4="","",SUMIFS(機種販売入力!$H$4:$H$503,機種販売入力!$C$4:$C$503,$B4,機種販売入力!$B$4:$B$503,"<>YM")) | F4: =IF($B4="","",N($D4)*E4) | I4: iPhone | J4: iPhone 17e(256GB) | K4: M | M4: =IF($J4="","",SUMIFS(機種販売入力!$H$4:$H$503,機種販売入力!$C$4:$C$503,$J4,機種販売入力!$B$4:$B$503,"YM")) | N4: =IF($J4="","",N($L4)*M4) | Q4: H | R4: 4
A5: iPhone | B5: iPhone 18 Pro(512GB) | C5: H | D5: 2 | E5: =IF($B5="","",SUMIFS(機種販売入力!$H$4:$H$503,機種販売入力!$C$4:$C$503,$B5,機種販売入力!$B$4:$B$503,"<>YM")) | F5: =IF($B5="","",N($D5)*E5) | I5: iPhone | J5: iPhone 17e(512GB) | K5: M | M5: =IF($J5="","",SUMIFS(機種販売入力!$H$4:$H$503,機種販売入力!$C$4:$C$503,$J5,機種販売入力!$B$4:$B$503,"YM")) | N5: =IF($J5="","",N($L5)*M5) | Q5: M | R5: 2
A6: iPhone | B6: iPhone 18 Pro(1TB) | C6: H | D6: 2 | E6: =IF($B6="","",SUMIFS(機種販売入力!$H$4:$H$503,機種販売入力!$C$4:$C$503,$B6,機種販売入力!$B$4:$B$503,"<>YM")) | F6: =IF($B6="","",N($D6)*E6) | I6: iPhone | J6: iPhone 16e(128GB) | K6: M | M6: =IF($J6="","",SUMIFS(機種販売入力!$H$4:$H$503,機種販売入力!$C$4:$C$503,$J6,機種販売入力!$B$4:$B$503,"YM")) | N6: =IF($J6="","",N($L6)*M6) | Q6: L | R6: 1
A7: iPhone | B7: iPhone 18 Pro(2TB) | C7: H | D7: 2 | E7: =IF($B7="","",SUMIFS(機種販売入力!$H$4:$H$503,機種販売入力!$C$4:$C$503,$B7,機種販売入力!$B$4:$B$503,"<>YM")) | F7: =IF($B7="","",N($D7)*E7) | I7: iPhone | J7: iPhone 16e(256GB) | K7: M | M7: =IF($J7="","",SUMIFS(機種販売入力!$H$4:$H$503,機種販売入力!$C$4:$C$503,$J7,機種販売入力!$B$4:$B$503,"YM")) | N7: =IF($J7="","",N($L7)*M7)
A8: iPhone | B8: iPhone 18 Pro Max(256GB) | C8: H | D8: 2 | E8: =IF($B8="","",SUMIFS(機種販売入力!$H$4:$H$503,機種販売入力!$C$4:$C$503,$B8,機種販売入力!$B$4:$B$503,"<>YM")) | F8: =IF($B8="","",N($D8)*E8) | I8: iPhone | J8: iPhone 16e(512GB) | K8: M | M8: =IF($J8="","",SUMIFS(機種販売入力!$H$4:$H$503,機種販売入力!$C$4:$C$503,$J8,機種販売入力!$B$4:$B$503,"YM")) | N8: =IF($J8="","",N($L8)*M8) | Q8: SB 戦略Pt合計 | R8: =SUM(F4:F363)
A9: iPhone | B9: iPhone 18 Pro Max(512GB) | C9: H | D9: 2 | E9: =IF($B9="","",SUMIFS(機種販売入力!$H$4:$H$503,機種販売入力!$C$4:$C$503,$B9,機種販売入力!$B$4:$B$503,"<>YM")) | F9: =IF($B9="","",N($D9)*E9) | I9: iPhone | J9: iPhone 16(128GB) | K9: M | M9: =IF($J9="","",SUMIFS(機種販売入力!$H$4:$H$503,機種販売入力!$C$4:$C$503,$J9,機種販売入力!$B$4:$B$503,"YM")) | N9: =IF($J9="","",N($L9)*M9) | Q9: YM 戦略Pt合計 | R9: =SUM(N4:N203)
A10: iPhone | B10: iPhone 18 Pro Max(1TB) | C10: H | D10: 2 | E10: =IF($B10="","",SUMIFS(機種販売入力!$H$4:$H$503,機種販売入力!$C$4:$C$503,$B10,機種販売入力!$B$4:$B$503,"<>YM")) | F10: =IF($B10="","",N($D10)*E10) | I10: iPhone | J10: iPhone 16(256GB) | K10: M | M10: =IF($J10="","",SUMIFS(機種販売入力!$H$4:$H$503,機種販売入力!$C$4:$C$503,$J10,機種販売入力!$B$4:$B$503,"YM")) | N10: =IF($J10="","",N($L10)*M10) | Q10: 合計 | R10: =R8+R9
A11: iPhone | B11: iPhone 18 Pro Max(2TB) | C11: H | D11: 2 | E11: =IF($B11="","",SUMIFS(機種販売入力!$H$4:$H$503,機種販売入力!$C$4:$C$503,$B11,機種販売入力!$B$4:$B$503,"<>YM")) | F11: =IF($B11="","",N($D11)*E11) | I11: iPhone | J11: iPhone 16(512GB) | K11: M | M11: =IF($J11="","",SUMIFS(機種販売入力!$H$4:$H$503,機種販売入力!$C$4:$C$503,$J11,機種販売入力!$B$4:$B$503,"YM")) | N11: =IF($J11="","",N($L11)*M11)
A12: iPhone | B12: iPhone 17(256GB) | C12: H | D12: 2 | E12: =IF($B12="","",SUMIFS(機種販売入力!$H$4:$H$503,機種販売入力!$C$4:$C$503,$B12,機種販売入力!$B$4:$B$503,"<>YM")) | F12: =IF($B12="","",N($D12)*E12) | I12: iPhone | J12: iPhone 15(128GB) | K12: M | M12: =IF($J12="","",SUMIFS(機種販売入力!$H$4:$H$503,機種販売入力!$C$4:$C$503,$J12,機種販売入力!$B$4:$B$503,"YM")) | N12: =IF($J12="","",N($L12)*M12)
A13: iPhone | B13: iPhone 17(512GB) | C13: H | D13: 2 | E13: =IF($B13="","",SUMIFS(機種販売入力!$H$4:$H$503,機種販売入力!$C$4:$C$503,$B13,機種販売入力!$B$4:$B$503,"<>YM")) | F13: =IF($B13="","",N($D13)*E13) | I13: iPhone | J13: iPhone 15(256GB) | K13: M | M13: =IF($J13="","",SUMIFS(機種販売入力!$H$4:$H$503,機種販売入力!$C$4:$C$503,$J13,機種販売入力!$B$4:$B$503,"YM")) | N13: =IF($J13="","",N($L13)*M13)
A14: iPhone | B14: iPhone Air(256GB) | C14: H | D14: 2 | E14: =IF($B14="","",SUMIFS(機種販売入力!$H$4:$H$503,機種販売入力!$C$4:$C$503,$B14,機種販売入力!$B$4:$B$503,"<>YM")) | F14: =IF($B14="","",N($D14)*E14) | I14: iPhone | J14: iPhone 15(512GB) | K14: M | M14: =IF($J14="","",SUMIFS(機種販売入力!$H$4:$H$503,機種販売入力!$C$4:$C$503,$J14,機種販売入力!$B$4:$B$503,"YM")) | N14: =IF($J14="","",N($L14)*M14)
A15: iPhone | B15: iPhone Air(512GB) | C15: H | D15: 2 | E15: =IF($B15="","",SUMIFS(機種販売入力!$H$4:$H$503,機種販売入力!$C$4:$C$503,$B15,機種販売入力!$B$4:$B$503,"<>YM")) | F15: =IF($B15="","",N($D15)*E15) | I15: iPhone | J15: iPhone 14(128GB) | K15: M | M15: =IF($J15="","",SUMIFS(機種販売入力!$H$4:$H$503,機種販売入力!$C$4:$C$503,$J15,機種販売入力!$B$4:$B$503,"YM")) | N15: =IF($J15="","",N($L15)*M15)
A16: iPhone | B16: iPhone Air(1TB) | C16: H | D16: 2 | E16: =IF($B16="","",SUMIFS(機種販売入力!$H$4:$H$503,機種販売入力!$C$4:$C$503,$B16,機種販売入力!$B$4:$B$503,"<>YM")) | F16: =IF($B16="","",N($D16)*E16) | I16: iPhone | J16: iPhone 14(256GB) | K16: M | M16: =IF($J16="","",SUMIFS(機種販売入力!$H$4:$H$503,機種販売入力!$C$4:$C$503,$J16,機種販売入力!$B$4:$B$503,"YM")) | N16: =IF($J16="","",N($L16)*M16)
A17: iPhone | B17: iPhone 17 Pro(256GB) | C17: M | E17: =IF($B17="","",SUMIFS(機種販売入力!$H$4:$H$503,機種販売入力!$C$4:$C$503,$B17,機種販売入力!$B$4:$B$503,"<>YM")) | F17: =IF($B17="","",N($D17)*E17) | I17: iPhone | J17: iPhone 14(512GB) | K17: M | M17: =IF($J17="","",SUMIFS(機種販売入力!$H$4:$H$503,機種販売入力!$C$4:$C$503,$J17,機種販売入力!$B$4:$B$503,"YM")) | N17: =IF($J17="","",N($L17)*M17)
A18: iPhone | B18: iPhone 17 Pro(512GB) | C18: M | E18: =IF($B18="","",SUMIFS(機種販売入力!$H$4:$H$503,機種販売入力!$C$4:$C$503,$B18,機種販売入力!$B$4:$B$503,"<>YM")) | F18: =IF($B18="","",N($D18)*E18) | I18: iPhone | J18: iPhone 13(128GB) | K18: M | M18: =IF($J18="","",SUMIFS(機種販売入力!$H$4:$H$503,機種販売入力!$C$4:$C$503,$J18,機種販売入力!$B$4:$B$503,"YM")) | N18: =IF($J18="","",N($L18)*M18) | O18: 46478
A19: iPhone | B19: iPhone 17 Pro(1TB) | C19: M | E19: =IF($B19="","",SUMIFS(機種販売入力!$H$4:$H$503,機種販売入力!$C$4:$C$503,$B19,機種販売入力!$B$4:$B$503,"<>YM")) | F19: =IF($B19="","",N($D19)*E19) | I19: iPhone | J19: iPhone 13(256GB) | K19: M | M19: =IF($J19="","",SUMIFS(機種販売入力!$H$4:$H$503,機種販売入力!$C$4:$C$503,$J19,機種販売入力!$B$4:$B$503,"YM")) | N19: =IF($J19="","",N($L19)*M19) | O19: 46478
A20: iPhone | B20: iPhone 17 Pro Max(256GB) | C20: M | E20: =IF($B20="","",SUMIFS(機種販売入力!$H$4:$H$503,機種販売入力!$C$4:$C$503,$B20,機種販売入力!$B$4:$B$503,"<>YM")) | F20: =IF($B20="","",N($D20)*E20) | I20: iPhone | J20: iPhone 13(512GB) | K20: M | M20: =IF($J20="","",SUMIFS(機種販売入力!$H$4:$H$503,機種販売入力!$C$4:$C$503,$J20,機種販売入力!$B$4:$B$503,"YM")) | N20: =IF($J20="","",N($L20)*M20) | O20: 46478
A21: iPhone | B21: iPhone 17 Pro Max(512GB) | C21: M | E21: =IF($B21="","",SUMIFS(機種販売入力!$H$4:$H$503,機種販売入力!$C$4:$C$503,$B21,機種販売入力!$B$4:$B$503,"<>YM")) | F21: =IF($B21="","",N($D21)*E21) | I21: iPhone | J21: iPhone SE(第3世代)(64GB) | K21: M | M21: =IF($J21="","",SUMIFS(機種販売入力!$H$4:$H$503,機種販売入力!$C$4:$C$503,$J21,機種販売入力!$B$4:$B$503,"YM")) | N21: =IF($J21="","",N($L21)*M21)
A22: iPhone | B22: iPhone 17 Pro Max(1TB) | C22: M | E22: =IF($B22="","",SUMIFS(機種販売入力!$H$4:$H$503,機種販売入力!$C$4:$C$503,$B22,機種販売入力!$B$4:$B$503,"<>YM")) | F22: =IF($B22="","",N($D22)*E22) | I22: iPhone | J22: iPhone SE(第3世代)(128GB) | K22: M | M22: =IF($J22="","",SUMIFS(機種販売入力!$H$4:$H$503,機種販売入力!$C$4:$C$503,$J22,機種販売入力!$B$4:$B$503,"YM")) | N22: =IF($J22="","",N($L22)*M22)
A23: iPhone | B23: iPhone 17 Pro Max(2TB) | C23: M | E23: =IF($B23="","",SUMIFS(機種販売入力!$H$4:$H$503,機種販売入力!$C$4:$C$503,$B23,機種販売入力!$B$4:$B$503,"<>YM")) | F23: =IF($B23="","",N($D23)*E23) | I23: iPhone | J23: iPhone SE(第3世代)(256GB) | K23: M | M23: =IF($J23="","",SUMIFS(機種販売入力!$H$4:$H$503,機種販売入力!$C$4:$C$503,$J23,機種販売入力!$B$4:$B$503,"YM")) | N23: =IF($J23="","",N($L23)*M23)
A24: iPhone | B24: iPhone 16(128GB) | C24: M | E24: =IF($B24="","",SUMIFS(機種販売入力!$H$4:$H$503,機種販売入力!$C$4:$C$503,$B24,機種販売入力!$B$4:$B$503,"<>YM")) | F24: =IF($B24="","",N($D24)*E24) | I24: Pixel | J24: Google Pixel 10a(128GB) | K24: M | L24: 4 | M24: =IF($J24="","",SUMIFS(機種販売入力!$H$4:$H$503,機種販売入力!$C$4:$C$503,$J24,機種販売入力!$B$4:$B$503,"YM")) | N24: =IF($J24="","",N($L24)*M24)
A25: iPhone | B25: iPhone 16(256GB) | C25: M | E25: =IF($B25="","",SUMIFS(機種販売入力!$H$4:$H$503,機種販売入力!$C$4:$C$503,$B25,機種販売入力!$B$4:$B$503,"<>YM")) | F25: =IF($B25="","",N($D25)*E25) | I25: Pixel | J25: Google Pixel 10a(256GB) | K25: M | L25: 4 | M25: =IF($J25="","",SUMIFS(機種販売入力!$H$4:$H$503,機種販売入力!$C$4:$C$503,$J25,機種販売入力!$B$4:$B$503,"YM")) | N25: =IF($J25="","",N($L25)*M25)
A26: iPhone | B26: iPhone 16(512GB) | C26: M | E26: =IF($B26="","",SUMIFS(機種販売入力!$H$4:$H$503,機種販売入力!$C$4:$C$503,$B26,機種販売入力!$B$4:$B$503,"<>YM")) | F26: =IF($B26="","",N($D26)*E26) | I26: Pixel | J26: Google Pixel 9a(128GB) | K26: M | L26: 4 | M26: =IF($J26="","",SUMIFS(機種販売入力!$H$4:$H$503,機種販売入力!$C$4:$C$503,$J26,機種販売入力!$B$4:$B$503,"YM")) | N26: =IF($J26="","",N($L26)*M26)
A27: iPhone | B27: iPhone 16 Plus(128GB) | C27: M | E27: =IF($B27="","",SUMIFS(機種販売入力!$H$4:$H$503,機種販売入力!$C$4:$C$503,$B27,機種販売入力!$B$4:$B$503,"<>YM")) | F27: =IF($B27="","",N($D27)*E27) | I27: Pixel | J27: Google Pixel 9a(256GB) | K27: M | L27: 4 | M27: =IF($J27="","",SUMIFS(機種販売入力!$H$4:$H$503,機種販売入力!$C$4:$C$503,$J27,機種販売入力!$B$4:$B$503,"YM")) | N27: =IF($J27="","",N($L27)*M27)
A28: iPhone | B28: iPhone 16 Plus(256GB) | C28: M | E28: =IF($B28="","",SUMIFS(機種販売入力!$H$4:$H$503,機種販売入力!$C$4:$C$503,$B28,機種販売入力!$B$4:$B$503,"<>YM")) | F28: =IF($B28="","",N($D28)*E28) | I28: Pixel | J28: Google Pixel 8a | K28: M | L28: 4 | M28: =IF($J28="","",SUMIFS(機種販売入力!$H$4:$H$503,機種販売入力!$C$4:$C$503,$J28,機種販売入力!$B$4:$B$503,"YM")) | N28: =IF($J28="","",N($L28)*M28) | O28: 46478
A29: iPhone | B29: iPhone 16 Plus(512GB) | C29: M | E29: =IF($B29="","",SUMIFS(機種販売入力!$H$4:$H$503,機種販売入力!$C$4:$C$503,$B29,機種販売入力!$B$4:$B$503,"<>YM")) | F29: =IF($B29="","",N($D29)*E29) | I29: Pixel | J29: Google Pixel 8 | K29: M | L29: 4 | M29: =IF($J29="","",SUMIFS(機種販売入力!$H$4:$H$503,機種販売入力!$C$4:$C$503,$J29,機種販売入力!$B$4:$B$503,"YM")) | N29: =IF($J29="","",N($L29)*M29)
A30: iPhone | B30: iPhone 16 Pro(128GB) | C30: M | E30: =IF($B30="","",SUMIFS(機種販売入力!$H$4:$H$503,機種販売入力!$C$4:$C$503,$B30,機種販売入力!$B$4:$B$503,"<>YM")) | F30: =IF($B30="","",N($D30)*E30) | I30: Pixel | J30: Google Pixel 7a | K30: M | L30: 4 | M30: =IF($J30="","",SUMIFS(機種販売入力!$H$4:$H$503,機種販売入力!$C$4:$C$503,$J30,機種販売入力!$B$4:$B$503,"YM")) | N30: =IF($J30="","",N($L30)*M30)
A31: iPhone | B31: iPhone 16 Pro(256GB) | C31: M | E31: =IF($B31="","",SUMIFS(機種販売入力!$H$4:$H$503,機種販売入力!$C$4:$C$503,$B31,機種販売入力!$B$4:$B$503,"<>YM")) | F31: =IF($B31="","",N($D31)*E31) | I31: Android | J31: Android One S10 | K31: L | M31: =IF($J31="","",SUMIFS(機種販売入力!$H$4:$H$503,機種販売入力!$C$4:$C$503,$J31,機種販売入力!$B$4:$B$503,"YM")) | N31: =IF($J31="","",N($L31)*M31)
A32: iPhone | B32: iPhone 16 Pro(512GB) | C32: M | E32: =IF($B32="","",SUMIFS(機種販売入力!$H$4:$H$503,機種販売入力!$C$4:$C$503,$B32,機種販売入力!$B$4:$B$503,"<>YM")) | F32: =IF($B32="","",N($D32)*E32) | I32: Android | J32: Galaxy A25 5G | K32: L | M32: =IF($J32="","",SUMIFS(機種販売入力!$H$4:$H$503,機種販売入力!$C$4:$C$503,$J32,機種販売入力!$B$4:$B$503,"YM")) | N32: =IF($J32="","",N($L32)*M32)
A33: iPhone | B33: iPhone 16 Pro(1TB) | C33: M | E33: =IF($B33="","",SUMIFS(機種販売入力!$H$4:$H$503,機種販売入力!$C$4:$C$503,$B33,機種販売入力!$B$4:$B$503,"<>YM")) | F33: =IF($B33="","",N($D33)*E33) | I33: Android | J33: moto g66y 5G | K33: L | M33: =IF($J33="","",SUMIFS(機種販売入力!$H$4:$H$503,機種販売入力!$C$4:$C$503,$J33,機種販売入力!$B$4:$B$503,"YM")) | N33: =IF($J33="","",N($L33)*M33)
A34: iPhone | B34: iPhone 16 Pro Max(256GB) | C34: M | E34: =IF($B34="","",SUMIFS(機種販売入力!$H$4:$H$503,機種販売入力!$C$4:$C$503,$B34,機種販売入力!$B$4:$B$503,"<>YM")) | F34: =IF($B34="","",N($D34)*E34) | I34: Android | J34: moto g64y 5G | K34: L | M34: =IF($J34="","",SUMIFS(機種販売入力!$H$4:$H$503,機種販売入力!$C$4:$C$503,$J34,機種販売入力!$B$4:$B$503,"YM")) | N34: =IF($J34="","",N($L34)*M34) | O34: 46478
A35: iPhone | B35: iPhone 16 Pro Max(512GB) | C35: M | E35: =IF($B35="","",SUMIFS(機種販売入力!$H$4:$H$503,機種販売入力!$C$4:$C$503,$B35,機種販売入力!$B$4:$B$503,"<>YM")) | F35: =IF($B35="","",N($D35)*E35) | I35: Android | J35: AQUOS Wish6 | K35: L | M35: =IF($J35="","",SUMIFS(機種販売入力!$H$4:$H$503,機種販売入力!$C$4:$C$503,$J35,機種販売入力!$B$4:$B$503,"YM")) | N35: =IF($J35="","",N($L35)*M35)
A36: iPhone | B36: iPhone 16 Pro Max(1TB) | C36: M | E36: =IF($B36="","",SUMIFS(機種販売入力!$H$4:$H$503,機種販売入力!$C$4:$C$503,$B36,機種販売入力!$B$4:$B$503,"<>YM")) | F36: =IF($B36="","",N($D36)*E36) | I36: Android | J36: AQUOS Wish5 | K36: L | M36: =IF($J36="","",SUMIFS(機種販売入力!$H$4:$H$503,機種販売入力!$C$4:$C$503,$J36,機種販売入力!$B$4:$B$503,"YM")) | N36: =IF($J36="","",N($L36)*M36)
A37: iPhone | B37: iPhone 17e(256GB) | C37: M | E37: =IF($B37="","",SUMIFS(機種販売入力!$H$4:$H$503,機種販売入力!$C$4:$C$503,$B37,機種販売入力!$B$4:$B$503,"<>YM")) | F37: =IF($B37="","",N($D37)*E37) | I37: Android | J37: AQUOS Wish4 | K37: L | M37: =IF($J37="","",SUMIFS(機種販売入力!$H$4:$H$503,機種販売入力!$C$4:$C$503,$J37,機種販売入力!$B$4:$B$503,"YM")) | N37: =IF($J37="","",N($L37)*M37) | O37: 46478
A38: iPhone | B38: iPhone 17e(512GB) | C38: M | E38: =IF($B38="","",SUMIFS(機種販売入力!$H$4:$H$503,機種販売入力!$C$4:$C$503,$B38,機種販売入力!$B$4:$B$503,"<>YM")) | F38: =IF($B38="","",N($D38)*E38) | I38: Android | J38: OPPO Reno15 A | K38: L | M38: =IF($J38="","",SUMIFS(機種販売入力!$H$4:$H$503,機種販売入力!$C$4:$C$503,$J38,機種販売入力!$B$4:$B$503,"YM")) | N38: =IF($J38="","",N($L38)*M38)
A39: iPhone | B39: iPhone 16e(128GB) | C39: M | E39: =IF($B39="","",SUMIFS(機種販売入力!$H$4:$H$503,機種販売入力!$C$4:$C$503,$B39,機種販売入力!$B$4:$B$503,"<>YM")) | F39: =IF($B39="","",N($D39)*E39) | I39: Android | J39: OPPO Reno13 A | K39: L | M39: =IF($J39="","",SUMIFS(機種販売入力!$H$4:$H$503,機種販売入力!$C$4:$C$503,$J39,機種販売入力!$B$4:$B$503,"YM")) | N39: =IF($J39="","",N($L39)*M39)
A40: iPhone | B40: iPhone 16e(256GB) | C40: M | E40: =IF($B40="","",SUMIFS(機種販売入力!$H$4:$H$503,機種販売入力!$C$4:$C$503,$B40,機種販売入力!$B$4:$B$503,"<>YM")) | F40: =IF($B40="","",N($D40)*E40) | I40: Android | J40: OPPO Reno11 A | K40: L | M40: =IF($J40="","",SUMIFS(機種販売入力!$H$4:$H$503,機種販売入力!$C$4:$C$503,$J40,機種販売入力!$B$4:$B$503,"YM")) | N40: =IF($J40="","",N($L40)*M40) | O40: 46478
...

Sheet グラフ用
A1: 日 | B1: 日付 | C1: 新規 | D1: MNP | E1: 固定 | F1: タブレット | G1: 電気 | H1: PPCD申込 | I1: SB Gold申込 | J1: 戦略機種(Pt) | K1: Watch | L1: 機変 | M1: DMM | N1: YouTube | O1: 理想ペース | R1: グラフ用の計算シートです(自動計算・編集不要)。
A2: 1 | B2: =進捗確認!B42 | C2: =IF(AND(進捗確認!$B42<>"",進捗確認!$A42<=進捗確認!$F$3,N(目標設定!$D$7)>0),SUM(進捗確認!C$42:C42)/目標設定!$D$7,NA()) | D2: =IF(AND(進捗確認!$B42<>"",進捗確認!$A42<=進捗確認!$F$3,N(目標設定!$D$8)>0),SUM(進捗確認!D$42:D42)/目標設定!$D$8,NA()) | E2: =IF(AND(進捗確認!$B42<>"",進捗確認!$A42<=進捗確認!$F$3,N(目標設定!$D$9)>0),SUM(進捗確認!E$42:E42)/目標設定!$D$9,NA()) | F2: =IF(AND(進捗確認!$B42<>"",進捗確認!$A42<=進捗確認!$F$3,N(目標設定!$D$10)>0),SUM(進捗確認!F$42:F42)/目標設定!$D$10,NA()) | G2: =IF(AND(進捗確認!$B42<>"",進捗確認!$A42<=進捗確認!$F$3,N(目標設定!$D$11)>0),SUM(進捗確認!G$42:G42)/目標設定!$D$11,NA()) | H2: =IF(AND(進捗確認!$B42<>"",進捗確認!$A42<=進捗確認!$F$3,N(目標設定!$D$12)>0),SUM(進捗確認!H$42:H42)/目標設定!$D$12,NA()) | I2: =IF(AND(進捗確認!$B42<>"",進捗確認!$A42<=進捗確認!$F$3,N(目標設定!$D$13)>0),SUM(進捗確認!I$42:I42)/目標設定!$D$13,NA()) | J2: =IF(AND(進捗確認!$B42<>"",進捗確認!$A42<=進捗確認!$F$3,N(目標設定!$D$14)>0),SUM(進捗確認!J$42:J42)/目標設定!$D$14,NA()) | K2: =IF(AND(進捗確認!$B42<>"",進捗確認!$A42<=進捗確認!$F$3,N(目標設定!$D$15)>0),SUM(進捗確認!K$42:K42)/目標設定!$D$15,NA()) | L2: =IF(AND(進捗確認!$B42<>"",進捗確認!$A42<=進捗確認!$F$3,N(目標設定!$D$16)>0),SUM(進捗確認!L$42:L42)/目標設定!$D$16,NA()) | M2: =IF(AND(進捗確認!$B42<>"",進捗確認!$A42<=進捗確認!$F$3,N(目標設定!$D$17)>0),SUM(進捗確認!M$42:M42)/目標設定!$D$17,NA()) | N2: =IF(AND(進捗確認!$B42<>"",進捗確認!$A42<=進捗確認!$F$3,N(目標設定!$D$18)>0),SUM(進捗確認!N$42:N42)/目標設定!$D$18,NA()) | O2: =IF(進捗確認!$B42="",NA(),$A2/進捗確認!$D$3)
A3: 2 | B3: =進捗確認!B43 | C3: =IF(AND(進捗確認!$B43<>"",進捗確認!$A43<=進捗確認!$F$3,N(目標設定!$D$7)>0),SUM(進捗確認!C$42:C43)/目標設定!$D$7,NA()) | D3: =IF(AND(進捗確認!$B43<>"",進捗確認!$A43<=進捗確認!$F$3,N(目標設定!$D$8)>0),SUM(進捗確認!D$42:D43)/目標設定!$D$8,NA()) | E3: =IF(AND(進捗確認!$B43<>"",進捗確認!$A43<=進捗確認!$F$3,N(目標設定!$D$9)>0),SUM(進捗確認!E$42:E43)/目標設定!$D$9,NA()) | F3: =IF(AND(進捗確認!$B43<>"",進捗確認!$A43<=進捗確認!$F$3,N(目標設定!$D$10)>0),SUM(進捗確認!F$42:F43)/目標設定!$D$10,NA()) | G3: =IF(AND(進捗確認!$B43<>"",進捗確認!$A43<=進捗確認!$F$3,N(目標設定!$D$11)>0),SUM(進捗確認!G$42:G43)/目標設定!$D$11,NA()) | H3: =IF(AND(進捗確認!$B43<>"",進捗確認!$A43<=進捗確認!$F$3,N(目標設定!$D$12)>0),SUM(進捗確認!H$42:H43)/目標設定!$D$12,NA()) | I3: =IF(AND(進捗確認!$B43<>"",進捗確認!$A43<=進捗確認!$F$3,N(目標設定!$D$13)>0),SUM(進捗確認!I$42:I43)/目標設定!$D$13,NA()) | J3: =IF(AND(進捗確認!$B43<>"",進捗確認!$A43<=進捗確認!$F$3,N(目標設定!$D$14)>0),SUM(進捗確認!J$42:J43)/目標設定!$D$14,NA()) | K3: =IF(AND(進捗確認!$B43<>"",進捗確認!$A43<=進捗確認!$F$3,N(目標設定!$D$15)>0),SUM(進捗確認!K$42:K43)/目標設定!$D$15,NA()) | L3: =IF(AND(進捗確認!$B43<>"",進捗確認!$A43<=進捗確認!$F$3,N(目標設定!$D$16)>0),SUM(進捗確認!L$42:L43)/目標設定!$D$16,NA()) | M3: =IF(AND(進捗確認!$B43<>"",進捗確認!$A43<=進捗確認!$F$3,N(目標設定!$D$17)>0),SUM(進捗確認!M$42:M43)/目標設定!$D$17,NA()) | N3: =IF(AND(進捗確認!$B43<>"",進捗確認!$A43<=進捗確認!$F$3,N(目標設定!$D$18)>0),SUM(進捗確認!N$42:N43)/目標設定!$D$18,NA()) | O3: =IF(進捗確認!$B43="",NA(),$A3/進捗確認!$D$3)
A4: 3 | B4: =進捗確認!B44 | C4: =IF(AND(進捗確認!$B44<>"",進捗確認!$A44<=進捗確認!$F$3,N(目標設定!$D$7)>0),SUM(進捗確認!C$42:C44)/目標設定!$D$7,NA()) | D4: =IF(AND(進捗確認!$B44<>"",進捗確認!$A44<=進捗確認!$F$3,N(目標設定!$D$8)>0),SUM(進捗確認!D$42:D44)/目標設定!$D$8,NA()) | E4: =IF(AND(進捗確認!$B44<>"",進捗確認!$A44<=進捗確認!$F$3,N(目標設定!$D$9)>0),SUM(進捗確認!E$42:E44)/目標設定!$D$9,NA()) | F4: =IF(AND(進捗確認!$B44<>"",進捗確認!$A44<=進捗確認!$F$3,N(目標設定!$D$10)>0),SUM(進捗確認!F$42:F44)/目標設定!$D$10,NA()) | G4: =IF(AND(進捗確認!$B44<>"",進捗確認!$A44<=進捗確認!$F$3,N(目標設定!$D$11)>0),SUM(進捗確認!G$42:G44)/目標設定!$D$11,NA()) | H4: =IF(AND(進捗確認!$B44<>"",進捗確認!$A44<=進捗確認!$F$3,N(目標設定!$D$12)>0),SUM(進捗確認!H$42:H44)/目標設定!$D$12,NA()) | I4: =IF(AND(進捗確認!$B44<>"",進捗確認!$A44<=進捗確認!$F$3,N(目標設定!$D$13)>0),SUM(進捗確認!I$42:I44)/目標設定!$D$13,NA()) | J4: =IF(AND(進捗確認!$B44<>"",進捗確認!$A44<=進捗確認!$F$3,N(目標設定!$D$14)>0),SUM(進捗確認!J$42:J44)/目標設定!$D$14,NA()) | K4: =IF(AND(進捗確認!$B44<>"",進捗確認!$A44<=進捗確認!$F$3,N(目標設定!$D$15)>0),SUM(進捗確認!K$42:K44)/目標設定!$D$15,NA()) | L4: =IF(AND(進捗確認!$B44<>"",進捗確認!$A44<=進捗確認!$F$3,N(目標設定!$D$16)>0),SUM(進捗確認!L$42:L44)/目標設定!$D$16,NA()) | M4: =IF(AND(進捗確認!$B44<>"",進捗確認!$A44<=進捗確認!$F$3,N(目標設定!$D$17)>0),SUM(進捗確認!M$42:M44)/目標設定!$D$17,NA()) | N4: =IF(AND(進捗確認!$B44<>"",進捗確認!$A44<=進捗確認!$F$3,N(目標設定!$D$18)>0),SUM(進捗確認!N$42:N44)/目標設定!$D$18,NA()) | O4: =IF(進捗確認!$B44="",NA(),$A4/進捗確認!$D$3)
A5: 4 | B5: =進捗確認!B45 | C5: =IF(AND(進捗確認!$B45<>"",進捗確認!$A45<=進捗確認!$F$3,N(目標設定!$D$7)>0),SUM(進捗確認!C$42:C45)/目標設定!$D$7,NA()) | D5: =IF(AND(進捗確認!$B45<>"",進捗確認!$A45<=進捗確認!$F$3,N(目標設定!$D$8)>0),SUM(進捗確認!D$42:D45)/目標設定!$D$8,NA()) | E5: =IF(AND(進捗確認!$B45<>"",進捗確認!$A45<=進捗確認!$F$3,N(目標設定!$D$9)>0),SUM(進捗確認!E$42:E45)/目標設定!$D$9,NA()) | F5: =IF(AND(進捗確認!$B45<>"",進捗確認!$A45<=進捗確認!$F$3,N(目標設定!$D$10)>0),SUM(進捗確認!F$42:F45)/目標設定!$D$10,NA()) | G5: =IF(AND(進捗確認!$B45<>"",進捗確認!$A45<=進捗確認!$F$3,N(目標設定!$D$11)>0),SUM(進捗確認!G$42:G45)/目標設定!$D$11,NA()) | H5: =IF(AND(進捗確認!$B45<>"",進捗確認!$A45<=進捗確認!$F$3,N(目標設定!$D$12)>0),SUM(進捗確認!H$42:H45)/目標設定!$D$12,NA()) | I5: =IF(AND(進捗確認!$B45<>"",進捗確認!$A45<=進捗確認!$F$3,N(目標設定!$D$13)>0),SUM(進捗確認!I$42:I45)/目標設定!$D$13,NA()) | J5: =IF(AND(進捗確認!$B45<>"",進捗確認!$A45<=進捗確認!$F$3,N(目標設定!$D$14)>0),SUM(進捗確認!J$42:J45)/目標設定!$D$14,NA()) | K5: =IF(AND(進捗確認!$B45<>"",進捗確認!$A45<=進捗確認!$F$3,N(目標設定!$D$15)>0),SUM(進捗確認!K$42:K45)/目標設定!$D$15,NA()) | L5: =IF(AND(進捗確認!$B45<>"",進捗確認!$A45<=進捗確認!$F$3,N(目標設定!$D$16)>0),SUM(進捗確認!L$42:L45)/目標設定!$D$16,NA()) | M5: =IF(AND(進捗確認!$B45<>"",進捗確認!$A45<=進捗確認!$F$3,N(目標設定!$D$17)>0),SUM(進捗確認!M$42:M45)/目標設定!$D$17,NA()) | N5: =IF(AND(進捗確認!$B45<>"",進捗確認!$A45<=進捗確認!$F$3,N(目標設定!$D$18)>0),SUM(進捗確認!N$42:N45)/目標設定!$D$18,NA()) | O5: =IF(進捗確認!$B45="",NA(),$A5/進捗確認!$D$3)
